Workbook
Name __123Graph_A: #REF!
Name __123Graph_X: #REF!
Name _AtRisk_SimSetting_AutomaticallyGenerateReports: 0
Name _AtRisk_SimSetting_AutomaticResultsDisplayMode: 0
Name _AtRisk_SimSetting_ConvergenceConfidenceLevel: 0.95
Name _AtRisk_SimSetting_ConvergencePercentileToTest: 0.9
Name _AtRisk_SimSetting_ConvergencePerformMeanTest: 1
Name _AtRisk_SimSetting_ConvergencePerformPercentileTest: 0
Name _AtRisk_SimSetting_ConvergencePerformStdDeviationTest: 0
Name _AtRisk_SimSetting_ConvergenceTestAllOutputs: 1
Name _AtRisk_SimSetting_ConvergenceTestingPeriod: 100
Name _AtRisk_SimSetting_ConvergenceTolerance: 0.03
Name _AtRisk_SimSetting_LiveUpdate: 1
Name _AtRisk_SimSetting_LiveUpdatePeriod: -1
Name _AtRisk_SimSetting_RandomNumberGenerator: 0
Name _AtRisk_SimSetting_ReportsList: 0
Name _AtRisk_SimSetting_SimNameCount: 0
Name _AtRisk_SimSetting_StdRecalcBehavior: 0
Name _AtRisk_SimSetting_StdRecalcWithoutRiskStatic: 0
Name _AtRisk_SimSetting_StdRecalcWithoutRiskStaticPercentile: 0.5
Name _Order1: 255
Name _Order2: 0
Name _Regression_Int: 1
Name dddd: #REF!
Name OPERATIVO: #REF!
Name RiskAfterRecalcMacro: ""
Name RiskAfterSimMacro: ""
Name RiskBeforeRecalcMacro: ""
Name RiskBeforeSimMacro: ""
Name RiskCollectDistributionSamples: 2
Name RiskFixedSeed: 1
Name RiskHasSettings: 5
Name RiskMinimizeOnStart: 0
Name RiskMonitorConvergence: 1
Name RiskNumIterations: 1000
Name RiskNumSimulations: 1
Name RiskPauseOnError: 0
Name RiskRunAfterRecalcMacro: 0
Name RiskRunAfterSimMacro: 0
Name RiskRunBeforeRecalcMacro: 0
Name RiskRunBeforeSimMacro: 0
Name RiskSamplingType: 2
Name RiskStandardRecalc: 1
Name RiskUpdateDisplay: 0
Name RiskUseDifferentSeedForEachSim: 0
Name RiskUseFixedSeed: 0
Name RiskUseMultipleCPUs: 0

Sheet EMP FISCALIZABLE
A3: 1 | E3: TAREO DE EMPLEADOS - MES DE JUNIO DEL 2021 | J3: 12 | K3: 13 | L3: 14 | M3: 15 | O3: 16 | P3: 17 | Q3: 18 | R3: 19 | S3: 20 | T3: 21 | U3: 22 | V3: 23 | X3: 24 | Y3: 25 | Z3: 26 | AA3: 27 | AB3: 28 | AC3: 29 | AD3: 30 | AE3: 31 | AG3: 32 | AH3: 33 | AI3: 34 | AJ3: 35 | AK3: 36 | AL3: 37 | AM3: 38 | AN3: 39 | AP3: 40 | AQ3: 41 | AR3: 42 | AS3: 43 | AT3: 44 | AU3: 45 | AV3: 46 | AW3: 47 | AY3: 48 | AZ3: 49 | BA3: 50 | BB3: 51 | BC3: 52 | BD3: 53 | BE3: 54 | BF3: 55 | BH3: 56 | BI3: 57 | BJ3: 58 | BK3: 59 | BL3: 60 | BM3: 61 | BN3: 62 | BO3: 63 | BQ3: 64 | BR3: 65 | BS3: 66 | BT3: 67 | BU3: 68 | BV3: 69 | BW3: 70 | BX3: 71 | BZ3: 72 | CA3: 73 | CB3: 74 | CC3: 75 | CD3: 76 | CE3: 77 | CF3: 78 | CG3: 79 | CI3: 80 | CJ3: 81 | CK3: 82 | CL3: 83 | CM3: 84 | CN3: 85 | CO3: 86 | CP3: 87 | CR3: 88 | CS3: 89 | CT3: 90 | CU3: 91 | CV3: 92 | CW3: 93 | CX3: 94 | CY3: 95 | DA3: 96 | DB3: 97 | DC3: 98 | DD3: 99 | DE3: 100 | DF3: 101 | DG3: 102 | DH3: 103 | DJ3: 104 | DK3: 105 | DL3: 106 | DM3: 107 | DN3: 108 | DO3: 109 | DP3: 110 | DQ3: 111 | DS3: 112 | DT3: 113 | DU3: 114 | DV3: 115 | DW3: 116 | DX3: 117 | DY3: 118 | DZ3: 119 | EB3: 120 | EC3: 121 | ED3: 122 | EE3: 123 | EF3: 124 | EG3: 125 | EH3: 126 | EI3: 127 | EK3: 128 | EL3: 129 | EM3: 130 | EN3: 131 | EO3: 132 | EP3: 133 | EQ3: 134 | ER3: 135 | ET3: 136 | EU3: 137 | EV3: 138 | EW3: 139 | EX3: 1 | EY3: 141 | EZ3: 142 | FA3: 143 | FC3: 144 | FD3: 145 | FE3: 146 | FF3: 147 | FG3: 148 | FH3: 149 | FI3: 150 | FJ3: 151 | FL3: 152 | FM3: 153 | FN3: 154 | FO3: 155 | FP3: 156 | FQ3: 157 | FR3: 158 | FS3: 159 | FU3: 160 | FV3: 161 | FW3: 162 | FX3: 163 | FY3: 164 | FZ3: 165 | GA3: 166 | GB3: 167 | GD3: 168 | GE3: 169 | GF3: 170 | GG3: 171 | GH3: 172 | GI3: 173 | GJ3: 174 | GK3: 175 | GM3: 176 | GN3: 177 | GO3: 178 | GP3: 179 | GQ3: 180 | GR3: 181 | GS3: 182 | GT3: 183 | GV3: 184 | GW3: 185 | GX3: 186 | GY3: 187 | GZ3: 188 | HA3: 189 | HB3: 190 | HC3: 191 | HE3: 192 | HF3: 193 | HG3: 194 | HH3: 195 | HI3: 196 | HJ3: 197 | HK3: 198 | HL3: 199 | HN3: 200 | HO3: 201 | HP3: 202 | HQ3: 203 | HR3: 204 | HS3: 205 | HT3: 206 | HU3: 207 | HW3: 208 | HX3: 209 | HY3: 210 | HZ3: 211 | IA3: 212 | IB3: 213 | IC3: 214 | ID3: 215 | IF3: 216 | IG3: 217 | IH3: 218 | II3: 219 | IJ3: 220 | IK3: 221 | IL3: 222 | IM3: 223 | IO3: 224 | IP3: 225 | IQ3: 226 | IR3: 227 | IS3: 228 | IT3: 229 | IU3: 230 | IV3: 231 | IX3: 232 | IY3: 233 | IZ3: 234 | JA3: 235 | JB3: 236 | JC3: 237 | JD3: 238 | JE3: 239 | JG3: 240 | JH3: 241 | JI3: 242 | JJ3: 243 | JK3: 244 | JL3: 245 | JM3: 246 | JN3: 247 | JP3: 248 | JQ3: 249 | JR3: 250 | JS3: 251 | JT3: 252 | JU3: 253 | JV3: 254 | JW3: 255 | JY3: 256
B4: Ciclo de Pago 01 al 30 de Junio - Haber basico
B5: Ciclo de HE: 15 de mayo al 14 de junio del 2021
A7: N° | B7: DNI | C7: COD. SAP | D7: UBICACIÓN | E7: APELLIDOS Y NOMBRES | F7: PUESTO | G7: FECHA INGRESO | H7: Fecha de ingreso Site | I7: FECHA DE CESE | J7: 44331 | S7: =J7+1 -> 44332 | AB7: =S7+1 -> 44333 | AK7: =AB7+1 -> 44334 | AT7: =AK7+1 -> 44335 | BC7: =AT7+1 -> 44336 | BL7: =BC7+1 -> 44337 | BU7: =BL7+1 -> 44338 | CD7: =BU7+1 -> 44339 | CM7: =CD7+1 -> 44340 | CV7: =CM7+1 -> 44341 | DE7: =CV7+1 -> 44342 | DN7: =DE7+1 -> 44343 | DW7: =DN7+1 -> 44344 | EF7: =DW7+1 -> 44345 | EO7: =EF7+1 -> 44346 | EX7: =EO7+1 -> 44347 | FG7: =EX7+1 -> 44348 | FP7: =FG7+1 -> 44349 | FY7: =FP7+1 -> 44350 | GH7: =FY7+1 -> 44351 | GQ7: =GH7+1 -> 44352 | GZ7: =GQ7+1 -> 44353 | HI7: =GZ7+1 -> 44354 | HR7: =HI7+1 -> 44355 | IA7: =HR7+1 -> 44356 | IJ7: =IA7+1 -> 44357 | IS7: =IJ7+1 -> 44358 | JB7: =IS7+1 -> 44359 | JK7: =JB7+1 -> 44360 | JT7: =JK7+1 -> 44361 | KC7: =JT7+1 -> 44362 | KL7: =KC7+1 -> 44363 | KU7: =KL7+1 -> 44364 | LD7: =KU7+1 -> 44365 | LM7: =LD7+1 -> 44366 | LV7: =LM7+1 -> 44367 | ME7: =LV7+1 -> 44368 | MN7: =ME7+1 -> 44369 | MW7: =MN7+1 -> 44370 | NF7: =MW7+1 -> 44371 | NO7: =NF7+1 -> 44372 | NX7: =NO7+1 -> 44373 | OG7: =NX7+1 -> 44374 | OP7: =OG7+1 -> 44375 | OY7: =OP7+1 -> 44376 | PH7: =OY7+1 -> 44377 | PR7: DIAS TRABAJADOS | PS7: DESCANSO SEMANAL | PT7: FERIANO NO LABORADO | PU7: TOTAL DIAS TRABAJADOS | PV7: DIAS DESCANSO MEDICO | PY7: DIAS SUBSIDIO | QB7: DIAS VACACIONES | QE7: DIAS LICENCIA SIN GOCE | QH7: DIAS LICENCIA CON GOCE | QK7: DIAS FALTA 1 | QN7: DIAS FALTA MES ANTERIOR | QQ7: TOTAL DIAS | QR7: DIAS REINTEGRO DE ESTRUCTURA SALARIAL | QS7: HORAS EXTRAS DEL MES | QV7: REINTEGRO DE HORAS EXTRAS | QY7: DETALLE REINTEGRO HHEE | QZ7: DEL MES | RA7: REINTEGRO
J8: Entrada | K8: Salida | L8: Día | M8: Total Horas | N8: Horas Efectivas | O8: Normal | P8: 0.25 | Q8: 0.35 | R8: 1 | S8: Entrada | T8: Salida | U8: Día | V8: Total Horas | W8: Horas Efectivas | X8: Normal | Y8: 0.25 | Z8: 0.35 | AA8: 1 | AB8: Entrada | AC8: Salida | AD8: Día | AE8: Total Horas | AF8: Horas Efectivas | AG8: Normal | AH8: 0.25 | AI8: 0.35 | AJ8: 1 | AK8: Entrada | AL8: Salida | AM8: Día | AN8: Total Horas | AO8: Horas Efectivas | AP8: Normal | AQ8: 0.25 | AR8: 0.35 | AS8: 1 | AT8: Entrada | AU8: Salida | AV8: Día | AW8: Total Horas | AX8: Horas Efectivas | AY8: Normal | AZ8: 0.25 | BA8: 0.35 | BB8: 1 | BC8: Entrada | BD8: Salida | BE8: Día | BF8: Total Horas | BG8: Horas Efectivas | BH8: Normal | BI8: 0.25 | BJ8: 0.35 | BK8: 1 | BL8: Entrada | BM8: Salida | BN8: Día | BO8: Total Horas | BP8: Horas Efectivas | BQ8: Normal | BR8: 0.25 | BS8: 0.35 | BT8: 1 | BU8: Entrada | BV8: Salida | BW8: Día | BX8: Total Horas | BY8: Horas Efectivas | BZ8: Normal | CA8: 0.25 | CB8: 0.35 | CC8: 1 | CD8: Entrada | CE8: Salida | CF8: Día | CG8: Total Horas | CH8: Horas Efectivas | CI8: Normal | CJ8: 0.25 | CK8: 0.35 | CL8: 1 | CM8: Entrada | CN8: Salida | CO8: Día | CP8: Total Horas | CQ8: Horas Efectivas | CR8: Normal | CS8: 0.25 | CT8: 0.35 | CU8: 1 | CV8: Entrada | CW8: Salida | CX8: Día | CY8: Total Horas | CZ8: Horas Efectivas | DA8: Normal | DB8: 0.25 | DC8: 0.35 | DD8: 1 | DE8: Entrada | DF8: Salida | DG8: Día | DH8: Total Horas | DI8: Horas Efectivas | DJ8: Normal | DK8: 0.25 | DL8: 0.35 | DM8: 1 | DN8: Entrada | DO8: Salida | DP8: Día | DQ8: Total Horas | DR8: Horas Efectivas | DS8: Normal | DT8: 0.25 | DU8: 0.35 | DV8: 1 | DW8: Entrada | DX8: Salida | DY8: Día | DZ8: Total Horas | EA8: Horas Efectivas | EB8: Normal | EC8: 0.25 | ED8: 0.35 | EE8: 1 | EF8: Entrada | EG8: Salida | EH8: Día | EI8: Total Horas | EJ8: Horas Efectivas | EK8: Normal | EL8: 0.25 | EM8: 0.35 | EN8: 1 | EO8: Entrada | EP8: Salida | EQ8: Día | ER8: Total Horas | ES8: Horas Efectivas | ET8: Normal | EU8: 0.25 | EV8: 0.35 | EW8: 1 | EX8: Entrada | EY8: Salida | EZ8: Día | FA8: Total Horas | FB8: Horas Efectivas | FC8: Normal | FD8: 0.25 | FE8: 0.35 | FF8: 1 | FG8: Entrada | FH8: Salida | FI8: Día | FJ8: Total Horas | FK8: Horas Efectivas | FL8: Normal | FM8: 0.25 | FN8: 0.35 | FO8: 1 | FP8: Entrada | FQ8: Salida | FR8: Día | FS8: Total Horas | FT8: Horas Efectivas | FU8: Normal | FV8: 0.25 | FW8: 0.35 | FX8: 1 | FY8: Entrada | FZ8: Salida | GA8: Día | GB8: Total Horas | GC8: Horas Efectivas | GD8: Normal | GE8: 0.25 | GF8: 0.35 | GG8: 1 | GH8: Entrada | GI8: Salida | GJ8: Día | GK8: Total Horas | GL8: Horas Efectivas | GM8: Normal | GN8: 0.25 | GO8: 0.35 | GP8: 1 | GQ8: Entrada | GR8: Salida | GS8: Día | GT8: Total Horas | GU8: Horas Efectivas | GV8: Normal | GW8: 0.25 | GX8: 0.35 | GY8: 1 | GZ8: Entrada | HA8: Salida | HB8: Día | HC8: Total Horas | HD8: Horas Efectivas | HE8: Normal | HF8: 0.25 | HG8: 0.35 | HH8: 1 | HI8: Entrada | HJ8: Salida | HK8: Día | HL8: Total Horas | HM8: Horas Efectivas | HN8: Normal | HO8: 0.25 | HP8: 0.35 | HQ8: 1 | HR8: Entrada | HS8: Salida | HT8: Día | HU8: Total Horas | HV8: Horas Efectivas | HW8: Normal | HX8: 0.25 | HY8: 0.35 | HZ8: 1 | IA8: Entrada | IB8: Salida | IC8: Día | ID8: Total Horas | IE8: Horas Efectivas | IF8: Normal | IG8: 0.25 | IH8: 0.35 | II8: 1 | IJ8: Entrada | IK8: Salida | IL8: Día | IM8: Total Horas | IN8: Horas Efectivas | IO8: Normal | IP8: 0.25 | IQ8: 0.35 | IR8: 1 | IS8: Entrada | IT8: Salida | IU8: Día | IV8: Total Horas | IW8: Horas Efectivas | IX8: Normal | IY8: 0.25 | IZ8: 0.35 | JA8: 1 | JB8: Entrada | JC8: Salida | JD8: Día | JE8: Total Horas | JF8: Horas Efectivas | JG8: Normal | JH8: 0.25 | JI8: 0.35 | JJ8: 1 | JK8: Entrada | JL8: Salida | JM8: Día | JN8: Total Horas | JO8: Horas Efectivas | JP8: Normal | JQ8: 0.25 | JR8: 0.35 | JS8: 1 | JT8: Entrada | JU8: Salida | JV8: Día | JW8: Total Horas | JX8: Horas Efectivas | JY8: Normal | JZ8: 0.25 | KA8: 0.35 | KB8: 1 | KC8: Entrada | KD8: Salida | KE8: Día | KF8: Total Horas | KG8: Horas Efectivas | KH8: Normal | KI8: 0.25 | KJ8: 0.35 | KK8: 1 | KL8: Entrada | KM8: Salida | KN8: Día | KO8: Total Horas | KP8: Horas Efectivas | KQ8: Normal | KR8: 0.25 | KS8: 0.35 | KT8: 1 | KU8: Entrada | KV8: Salida | KW8: Día | KX8: Total Horas | KY8: Horas Efectivas | KZ8: Normal | LA8: 0.25 | LB8: 0.35 | LC8: 1 | LD8: Entrada | LE8: Salida | LF8: Día | LG8: Total Horas | LH8: Horas Efectivas | LI8: Normal | LJ8: 0.25 | LK8: 0.35 | LL8: 1 | LM8: Entrada | LN8: Salida | LO8: Día | LP8: Total Horas | LQ8: Horas Efectivas | LR8: Normal | LS8: 0.25 | LT8: 0.35 | LU8: 1 | LV8: Entrada | LW8: Salida | LX8: Día | LY8: Total Horas | LZ8: Horas Efectivas | MA8: Normal | MB8: 0.25 | MC8: 0.35 | MD8: 1 | ME8: Entrada | MF8: Salida | MG8: Día | MH8: Total Horas | MI8: Horas Efectivas | MJ8: Normal | MK8: 0.25 | ML8: 0.35 | MM8: 1 | MN8: Entrada | MO8: Salida | MP8: Día | MQ8: Total Horas | MR8: Horas Efectivas | MS8: Normal | MT8: 0.25 | MU8: 0.35 | MV8: 1 | MW8: Entrada | MX8: Salida | MY8: Día | MZ8: Total Horas | NA8: Horas Efectivas | NB8: Normal | NC8: 0.25 | ND8: 0.35 | NE8: 1 | NF8: Entrada | NG8: Salida | NH8: Día | NI8: Total Horas | NJ8: Horas Efectivas | NK8: Normal | NL8: 0.25 | NM8: 0.35 | NN8: 1 | NO8: Entrada | NP8: Salida | NQ8: Día | NR8: Total Horas | NS8: Horas Efectivas | NT8: Normal | NU8: 0.25 | NV8: 0.35 | NW8: 1 | NX8: Entrada | NY8: Salida | NZ8: Día | OA8: Total Horas | OB8: Horas Efectivas | OC8: Normal | OD8: 0.25 | OE8: 0.35 | OF8: 1 | OG8: Entrada | OH8: Salida | OI8: Día | OJ8: Total Horas | OK8: Horas Efectivas | OL8: Normal | OM8: 0.25 | ON8: 0.35 | OO8: 1 | OP8: Entrada | OQ8: Salida | OR8: Día | OS8: Total Horas | OT8: Horas Efectivas | OU8: Normal | OV8: 0.25 | OW8: 0.35 | OX8: 1 | OY8: Entrada | OZ8: Salida | PA8: Día | PB8: Total Horas | PC8: Horas Efectivas | PD8: Normal | PE8: 0.25 | PF8: 0.35 | PG8: 1 | PH8: Entrada | PI8: Salida | PJ8: Día | PK8: Total Horas | PL8: Horas Efectivas | PM8: Normal | PN8: 0.25 | PO8: 0.35 | PP8: 1 | PV8: DESCANSO MEDICO | PW8: FECHA INICIO | PX8: FECHA TERMINO | PY8: SUBSIDIO | PZ8: FECHA INICIO | QA8: FECHA TERMINO | QB8: VACACIONES | QC8: FECHA INICIO | QD8: FECHA TERMINO | QE8: LSG | QF8: FECHA INICIO | QG8: FECHA TERMINO | QH8: LCG | QI8: FECHA INICIO | QJ8: FECHA TERMINO | QK8: FALTA1 | QL8: FECHA INICIO | QM8: FECHA TERMINO | QN8: FALTA1 | QO8: FECHA INICIO | QP8: FECHA TERMINO | QS8: 0.25 | QT8: 0.35 | QU8: DSO O FERIADO | QV8: 0.25 | QW8: 0.35 | QX8: DSO O FERIADO | QZ8: ASIGNACION POR TRANSPORTE | RA8: ASIGNACION POR TRANSPORTE | RB8: OTROS INGRESOS | RC8: NUEVO HABER BASICO (INCREMENTO O REDUCCION DE SUELDO) | RD8: FECHA DE FIN? | RE8: CONCEPTO 1 | RF8: CONCEPTO 2 | RG8: Bono Nocturno
JZ9: =IF(JV9="NOR",IF(JW9>10,2,IF(JW9>8,(JW9-JY9),0)),0) -> 0 | KA9: =IF(JV9="NOR",IF(JW9<10,0,IF(JW9>10,(JW9-(JY9+JZ9)),0)),0) -> 0 | KB9: =IF(JV9="DOM",JW9,0) -> 0
A10: 1 | B10: 80124762 | D10: PROYECTO | E10: ALLEMAN LLASACA KARIN GUISELA | F10: VIGÍA | G10: 44348 | H10: 44348 | J10: 0 | K10: 0 | L10: NA | M10: =SUM(K10-J10) -> 0 | N10: =IF(M10>1,M10-1,0) -> 0 | O10: =IF(D10="STAFF",IF(L10="NOR",IF(N10>8.5,8.5,N10),0),IF(L10="NOR",IF(N10>8,8,N10),IF(D10="CAMPO",IF(L10="NOR",IF(N10>8,8,N10),0),IF(L10="NOR",IF(N10>8,8,N10),0)))) -> 0 | P10: =IF(L10="NOR",IF(N10>10,2,IF(N10>8,(N10-O10),0)),0) -> 0 | Q10: =IF(L10="NOR",IF(N10<10,0,IF(N10>10,(N10-(O10+P10)),0)),0) -> 0 | R10: =IF(L10="DOM",N10,0) -> 0 | S10: 0 | T10: 0 | U10: NA | V10: =SUM(T10-S10) -> 0 | W10: =IF(V10>1,V10-1,0) -> 0 | X10: =IF(D10="STAFF",IF(U10="NOR",IF(W10>8.5,8.5,W10),0),IF(U10="NOR",IF(W10>8,8,W10),IF(M10="CAMPO",IF(U10="NOR",IF(W10>8,8,W10),0),IF(U10="NOR",IF(W10>8,8,W10),0)))) -> 0 | Y10: =IF(U10="NOR",IF(W10>10,2,IF(W10>8,(W10-X10),0)),0) -> 0 | Z10: =IF(U10="NOR",IF(W10<10,0,IF(W10>10,(W10-(X10+Y10)),0)),0) -> 0 | AA10: =IF(U10="DOM",W10,0) -> 0 | AB10: 0 | AC10: 0 | AD10: NA | AE10: =SUM(AC10-AB10) -> 0 | AF10: =IF(AE10>1,AE10-1,0) -> 0 | AG10: =IF(D10="STAFF",IF(AD10="NOR",IF(AF10>8.5,8.5,AF10),0),IF(AD10="NOR",IF(AF10>8,8,AF10),IF(AE10="CAMPO",IF(AD10="NOR",IF(AF10>8,8,AF10),0),IF(AD10="NOR",IF(AF10>8,8,AF10),0)))) -> 0 | AH10: =IF(AD10="NOR",IF(AF10>10,2,IF(AF10>8,(AF10-AG10),0)),0) -> 0 | AI10: =IF(AD10="NOR",IF(AF10<10,0,IF(AF10>10,(AF10-(AG10+AH10)),0)),0) -> 0 | AJ10: =IF(AD10="DOM",AF10,0) -> 0 | AK10: 0 | AL10: 0 | AM10: NA | AN10: =SUM(AL10-AK10) -> 0 | AO10: =IF(AN10>1,AN10-1,0) -> 0 | AP10: =IF(D10="PROYECTO",IF(AM10="NOR",IF(AO10>8,8,AO10),0),IF(AM10="NOR",IF(AO10>8,8,AO10),0)) -> 0 | AQ10: =IF(AM10="NOR",IF(AO10>10,2,IF(AO10>8,(AO10-AP10),0)),0) -> 0 | AR10: =IF(AM10="NOR",IF(AO10<10,0,IF(AO10>10,(AO10-(AP10+AQ10)),0)),0) -> 0 | AS10: =IF(AM10="DOM",AO10,0) -> 0 | AT10: 0 | AU10: 0 | AV10: NA | AW10: =SUM(AU10-AT10) -> 0 | AX10: =IF(AW10>1,AW10-1,0) -> 0 | AY10: =IF(AO10="PROYECTO",IF(AV10="NOR",IF(AX10>8,8,AX10),0),IF(AV10="NOR",IF(AX10>8,8,AX10),0)) -> 0 | AZ10: =IF(AV10="NOR",IF(AX10>10,2,IF(AX10>8,(AX10-AY10),0)),0) -> 0 | BA10: =IF(AV10="NOR",IF(AX10<10,0,IF(AX10>10,(AX10-(AY10+AZ10)),0)),0) -> 0 | BB10: =IF(AV10="DOM",AX10,0) -> 0 | BC10: 0 | BD10: 0 | BE10: NA | BF10: =SUM(BD10-BC10) -> 0 | BG10: =IF(BF10>1,BF10-1,0) -> 0 | BH10: =IF(D10="STAFF",IF(BE10="NOR",IF(BG10>8.5,8.5,BG10),0),IF(BE10="NOR",IF(BG10>8,8,BG10),IF(BF10="CAMPO",IF(BE10="NOR",IF(BG10>8,8,BG10),0),IF(BE10="NOR",IF(BG10>8,8,BG10),0)))) -> 0 | BI10: =IF(BE10="NOR",IF(BG10>10,2,IF(BG10>8,(BG10-BH10),0)),0) -> 0 | BJ10: =IF(BE10="NOR",IF(BG10<10,0,IF(BG10>10,(BG10-(BH10+BI10)),0)),0) -> 0 | BK10: =IF(BE10="DOM",BG10,0) -> 0 | BL10: 0 | BM10: 0 | BN10: NA | BO10: =SUM(BM10-BL10) -> 0 | BP10: =IF(BO10>1,BO10-1,0) -> 0 | BQ10: =IF(D10="STAFF",IF(BN10="NOR",IF(BP10>8.5,8.5,BP10),0),IF(BN10="NOR",IF(BP10>8,8,BP10),IF(BO10="CAMPO",IF(BN10="NOR",IF(BP10>8,8,BP10),0),IF(BN10="NOR",IF(BP10>8,8,BP10),0)))) -> 0 | BR10: =IF(BN10="NOR",IF(BP10>10,2,IF(BP10>8,(BP10-BQ10),0)),0) -> 0 | BS10: =IF(BN10="NOR",IF(BP10<10,0,IF(BP10>10,(BP10-(BQ10+BR10)),0)),0) -> 0 | BT10: =IF(BN10="DOM",BP10,0) -> 0 | BU10: 0 | BV10: 0 | BW10: NA | BX10: =SUM(BV10-BU10) -> 0 | BY10: =IF(BX10>1,BX10-1,0) -> 0 | BZ10: =IF(D10="STAFF",IF(BW10="NOR",IF(BY10>8.5,8.5,BY10),0),IF(BW10="NOR",IF(BY10>8,8,BY10),IF(BX10="CAMPO",IF(BW10="NOR",IF(BY10>8,8,BY10),0),IF(BW10="NOR",IF(BY10>8,8,BY10),0)))) -> 0 | CA10: =IF(BW10="NOR",IF(BY10>10,2,IF(BY10>8,(BY10-BZ10),0)),0) -> 0 | CB10: =IF(BW10="NOR",IF(BY10<10,0,IF(BY10>10,(BY10-(BZ10+CA10)),0)),0) -> 0 | CC10: =IF(BW10="DOM",BY10,0) -> 0 | CD10: 0 | CE10: 0 | CF10: NA | CG10: =SUM(CE10-CD10) -> 0 | CH10: =IF(CG10>1,CG10-1,0) -> 0 | CI10: =IF(D10="STAFF",IF(CF10="NOR",IF(CH10>8.5,8.5,CH10),0),IF(CF10="NOR",IF(CH10>8,8,CH10),IF(CG10="CAMPO",IF(CF10="NOR",IF(CH10>8,8,CH10),0),IF(CF10="NOR",IF(CH10>8,8,CH10),0)))) -> 0 | CJ10: =IF(CF10="NOR",IF(CH10>10,2,IF(CH10>8,(CH10-CI10),0)),0) -> 0 | CK10: =IF(CF10="NOR",IF(CH10<10,0,IF(CH10>10,(CH10-(CI10+CJ10)),0)),0) -> 0 | CL10: =IF(CF10="DOM",CH10,0) -> 0 | CM10: 0 | CN10: 0 | CO10: NA | CP10: =SUM(CN10-CM10) -> 0 | CQ10: =IF(CP10>1,CP10-1,0) -> 0 | CR10: =IF(D10="STAFF",IF(CO10="NOR",IF(CQ10>8.5,8.5,CQ10),0),IF(CO10="NOR",IF(CQ10>8,8,CQ10),IF(CP10="CAMPO",IF(CO10="NOR",IF(CQ10>8,8,CQ10),0),IF(CO10="NOR",IF(CQ10>8,8,CQ10),0)))) -> 0 | CS10: =IF(CO10="NOR",IF(CQ10>10,2,IF(CQ10>8,(CQ10-CR10),0)),0) -> 0 | CT10: =IF(CO10="NOR",IF(CQ10<10,0,IF(CQ10>10,(CQ10-(CR10+CS10)),0)),0) -> 0 | CU10: =IF(CO10="DOM",CQ10,0) -> 0 | CV10: 0 | CW10: 0 | CX10: NA | CY10: =SUM(CW10-CV10) -> 0 | CZ10: =IF(CY10>1,CY10-1,0) -> 0 | DA10: =IF(CQ10="PROYECTO",IF(CX10="NOR",IF(CZ10>8,8,CZ10),0),IF(CX10="NOR",IF(CZ10>8,8,CZ10),0)) -> 0 | DB10: =IF(CX10="NOR",IF(CZ10>10,2,IF(CZ10>8,(CZ10-DA10),0)),0) -> 0 | DC10: =IF(CX10="NOR",IF(CZ10<10,0,IF(CZ10>10,(CZ10-(DA10+DB10)),0)),0) -> 0 | DD10: =IF(CX10="DOM",CZ10,0) -> 0 | DE10: 0 | DF10: 0 | DG10: NA | DH10: =SUM(DF10-DE10) -> 0 | DI10: =IF(DH10>1,DH10-1,0) -> 0 | DJ10: =IF(CZ10="PROYECTO",IF(DG10="NOR",IF(DI10>8,8,DI10),0),IF(DG10="NOR",IF(DI10>8,8,DI10),0)) -> 0 | DK10: =IF(DG10="NOR",IF(DI10>10,2,IF(DI10>8,(DI10-DJ10),0)),0) -> 0 | DL10: =IF(DG10="NOR",IF(DI10<10,0,IF(DI10>10,(DI10-(DJ10+DK10)),0)),0) -> 0 | DM10: =IF(DG10="DOM",DI10,0) -> 0 | DN10: 0 | DO10: 0 | DP10: NA | DQ10: =SUM(DO10-DN10) -> 0 | DR10: =IF(DQ10>1,DQ10-1,0) -> 0 | DS10: =IF(D10="STAFF",IF(DP10="NOR",IF(DR10>8.5,8.5,DR10),0),IF(DP10="NOR",IF(DR10>8,8,DR10),IF(DQ10="CAMPO",IF(DP10="NOR",IF(DR10>8,8,DR10),0),IF(DP10="NOR",IF(DR10>8,8,DR10),0)))) -> 0 | DT10: =IF(DP10="NOR",IF(DR10>10,2,IF(DR10>8,(DR10-DS10),0)),0) -> 0 | DU10: =IF(DP10="NOR",IF(DR10<10,0,IF(DR10>10,(DR10-(DS10+DT10)),0)),0) -> 0 | DV10: =IF(DP10="DOM",DR10,0) -> 0 | DW10: 0 | DX10: 0 | DY10: NA | DZ10: =SUM(DX10-DW10) -> 0 | EA10: =IF(DZ10>1,DZ10-1,0) -> 0 | EB10: =IF(D10="STAFF",IF(DY10="NOR",IF(EA10>8.5,8.5,EA10),0),IF(DY10="NOR",IF(EA10>8,8,EA10),IF(DZ10="CAMPO",IF(DY10="NOR",IF(EA10>8,8,EA10),0),IF(DY10="NOR",IF(EA10>8,8,EA10),0)))) -> 0 | EC10: =IF(DY10="NOR",IF(EA10>10,2,IF(EA10>8,(EA10-EB10),0)),0) -> 0 | ED10: =IF(DY10="NOR",IF(EA10<10,0,IF(EA10>10,(EA10-(EB10+EC10)),0)),0) -> 0 | EE10: =IF(DY10="DOM",EA10,0) -> 0 | EF10: 0 | EG10: 0 | EH10: NA | EI10: =SUM(EG10-EF10) -> 0 | EJ10: =IF(EI10>1,EI10-1,0) -> 0 | EK10: =IF(D10="STAFF",IF(EH10="NOR",IF(EJ10>8.5,8.5,EJ10),0),IF(EH10="NOR",IF(EJ10>8,8,EJ10),IF(EI10="CAMPO",IF(EH10="NOR",IF(EJ10>8,8,EJ10),0),IF(EH10="NOR",IF(EJ10>8,8,EJ10),0)))) -> 0 | EL10: =IF(EH10="NOR",IF(EJ10>10,2,IF(EJ10>8,(EJ10-EK10),0)),0) -> 0 | EM10: =IF(EH10="NOR",IF(EJ10<10,0,IF(EJ10>10,(EJ10-(EK10+EL10)),0)),0) -> 0 | EN10: =IF(EH10="DOM",EJ10,0) -> 0 | EO10: 0 | EP10: 0 | EQ10: NA | ER10: =SUM(EP10-EO10) -> 0 | ES10: =IF(ER10>1,ER10-1,0) -> 0 | ET10: =IF(D10="STAFF",IF(EQ10="NOR",IF(ES10>8.5,8.5,ES10),0),IF(EQ10="NOR",IF(ES10>8,8,ES10),IF(ER10="CAMPO",IF(EQ10="NOR",IF(ES10>8,8,ES10),0),IF(EQ10="NOR",IF(ES10>8,8,ES10),0)))) -> 0 | EU10: =IF(EQ10="NOR",IF(ES10>10,2,IF(ES10>8,(ES10-ET10),0)),0) -> 0 | EV10: =IF(EQ10="NOR",IF(ES10<10,0,IF(ES10>10,(ES10-(ET10+EU10)),0)),0) -> 0 | EW10: =IF(EQ10="DOM",ES10,0) -> 0 | EX10: 0 | EY10: 0 | EZ10: NA | FA10: =SUM(EY10-EX10) -> 0 | FB10: =IF(FA10>1,FA10-1,0) -> 0 | FC10: =IF(D10="STAFF",IF(EZ10="NOR",IF(FB10>8.5,8.5,FB10),0),IF(EZ10="NOR",IF(FB10>8,8,FB10),IF(FA10="CAMPO",IF(EZ10="NOR",IF(FB10>8,8,FB10),0),IF(EZ10="NOR",IF(FB10>8,8,FB10),0)))) -> 0 | FD10: =IF(EZ10="NOR",IF(FB10>10,2,IF(FB10>8,(FB10-FC10),0)),0) -> 0 | FE10: =IF(EZ10="NOR",IF(FB10<10,0,IF(FB10>10,(FB10-(FC10+FD10)),0)),0) -> 0 | FF10: =IF(EZ10="DOM",FB10,0) -> 0 | FG10: 7 | FH10: 18 | FI10: NOR | FJ10: =SUM(FH10-FG10) -> 11 | FK10: =IF(FJ10>1,FJ10-1,0) -> 10 | FL10: =IF(D10="STAFF",IF(FI10="NOR",IF(FK10>8.5,8.5,FK10),0),IF(FI10="NOR",IF(FK10>8,8,FK10),IF(FJ10="CAMPO",IF(FI10="NOR",IF(FK10>8,8,FK10),0),IF(FI10="NOR",IF(FK10>8,8,FK10),0)))) -> 8 | FM10: =IF(FI10="NOR",IF(FK10>10,2,IF(FK10>8,(FK10-FL10),0)),0) -> 2 | FN10: =IF(FI10="NOR",IF(FK10<10,0,IF(FK10>10,(FK10-(FL10+FM10)),0)),0) -> 0 | FO10: =IF(FI10="DOM",FK10,0) -> 0 | FP10: 7 | FQ10: 18 | FR10: NOR | FS10: =SUM(FQ10-FP10) -> 11 | FT10: =IF(FS10>1,FS10-1,0) -> 10 | FU10: =IF(FK10="PROYECTO",IF(FR10="NOR",IF(FT10>8,8,FT10),0),IF(FR10="NOR",IF(FT10>8,8,FT10),0)) -> 8 | FV10: =IF(FR10="NOR",IF(FT10>10,2,IF(FT10>8,(FT10-FU10),0)),0) -> 2 | FW10: =IF(FR10="NOR",IF(FT10<10,0,IF(FT10>10,(FT10-(FU10+FV10)),0)),0) -> 0 | FX10: =IF(FR10="DOM",FT10,0) -> 0 | FY10: 7 | FZ10: 18 | GA10: NOR | GB10: =SUM(FZ10-FY10) -> 11 | GC10: =IF(GB10>1,GB10-1,0) -> 10 | GD10: =IF(D10="STAFF",IF(GA10="NOR",IF(GC10>8.5,8.5,GC10),0),IF(GA10="NOR",IF(GC10>8,8,GC10),IF(GB10="CAMPO",IF(GA10="NOR",IF(GC10>8,8,GC10),0),IF(GA10="NOR",IF(GC10>8,8,GC10),0)))) -> 8 | GE10: =IF(GA10="NOR",IF(GC10>10,2,IF(GC10>8,(GC10-GD10),0)),0) -> 2 | GF10: =IF(GA10="NOR",IF(GC10<10,0,IF(GC10>10,(GC10-(GD10+GE10)),0)),0) -> 0 | GG10: =IF(GA10="DOM",GC10,0) -> 0 | GH10: 7 | GI10: 18 | GJ10: NOR | GK10: =SUM(GI10-GH10) -> 11 | GL10: =IF(GK10>1,GK10-1,0) -> 10 | GM10: =IF(D10="STAFF",IF(GJ10="NOR",IF(GL10>8.5,8.5,GL10),0),IF(GJ10="NOR",IF(GL10>8,8,GL10),IF(GK10="CAMPO",IF(GJ10="NOR",IF(GL10>8,8,GL10),0),IF(GJ10="NOR",IF(GL10>8,8,GL10),0)))) -> 8 | GN10: =IF(GJ10="NOR",IF(GL10>10,2,IF(GL10>8,(GL10-GM10),0)),0) -> 2 | GO10: =IF(GJ10="NOR",IF(GL10<10,0,IF(GL10>10,(GL10-(GM10+GN10)),0)),0) -> 0 | GP10: =IF(GJ10="DOM",GL10,0) -> 0 | GQ10: 7 | GR10: 18 | GS10: NOR | GT10: =SUM(GR10-GQ10) -> 11 | GU10: =IF(GT10>1,GT10-1,0) -> 10 | GV10: =IF(D10="STAFF",IF(GS10="NOR",IF(GU10>8.5,8.5,GU10),0),IF(GS10="NOR",IF(GU10>8,8,GU10),IF(GT10="CAMPO",IF(GS10="NOR",IF(GU10>8,8,GU10),0),IF(GS10="NOR",IF(GU10>8,8,GU10),0)))) -> 8 | GW10: =IF(GS10="NOR",IF(GU10>10,2,IF(GU10>8,(GU10-GV10),0)),0) -> 2 | GX10: =IF(GS10="NOR",IF(GU10<10,0,IF(GU10>10,(GU10-(GV10+GW10)),0)),0) -> 0 | GY10: =IF(GS10="DOM",GU10,0) -> 0 | GZ10: 0 | HA10: 0 | HB10: DS | HC10: =SUM(HA10-GZ10) -> 0 | HD10: =IF(HC10>1,HC10-1,0) -> 0 | HE10: =IF(D10="STAFF",IF(HB10="NOR",IF(HD10>8.5,8.5,HD10),0),IF(HB10="NOR",IF(HD10>8,8,HD10),IF(HC10="CAMPO",IF(HB10="NOR",IF(HD10>8,8,HD10),0),IF(HB10="NOR",IF(HD10>8,8,HD10),0)))) -> 0 | HF10: =IF(HB10="NOR",IF(HD10>10,2,IF(HD10>8,(HD10-HE10),0)),0) -> 0 | HG10: =IF(HB10="NOR",IF(HD10<10,0,IF(HD10>10,(HD10-(HE10+HF10)),0)),0) -> 0 | HH10: =IF(HB10="DOM",HD10,0) -> 0 | HI10: 7 | HJ10: 18 | HK10: NOR | HL10: =SUM(HJ10-HI10) -> 11 | HM10: =IF(HL10>1,HL10-1,0) -> 10 | HN10: =IF(D10="STAFF",IF(HK10="NOR",IF(HM10>8.5,8.5,HM10),0),IF(HK10="NOR",IF(HM10>8,8,HM10),IF(HL10="CAMPO",IF(HK10="NOR",IF(HM10>8,8,HM10),0),IF(HK10="NOR",IF(HM10>8,8,HM10),0)))) -> 8 | HO10: =IF(HK10="NOR",IF(HM10>10,2,IF(HM10>8,(HM10-HN10),0)),0) -> 2 | HP10: =IF(HK10="NOR",IF(HM10<10,0,IF(HM10>10,(HM10-(HN10+HO10)),0)),0) -> 0 | HQ10: =IF(HK10="DOM",HM10,0) -> 0 | HR10: 7 | HS10: 18 | HT10: NOR | HU10: =SUM(HS10-HR10) -> 11 | HV10: =IF(HU10>1,HU10-1,0) -> 10 | HW10: =IF(D10="STAFF",IF(HT10="NOR",IF(HV10>8.5,8.5,HV10),0),IF(HT10="NOR",IF(HV10>8,8,HV10),IF(HU10="CAMPO",IF(HT10="NOR",IF(HV10>8,8,HV10),0),IF(HT10="NOR",IF(HV10>8,8,HV10),0)))) -> 8 | HX10: =IF(HT10="NOR",IF(HV10>10,2,IF(HV10>8,(HV10-HW10),0)),0) -> 2 | HY10: =IF(HT10="NOR",IF(HV10<10,0,IF(HV10>10,(HV10-(HW10+HX10)),0)),0) -> 0 | HZ10: =IF(HT10="DOM",HV10,0) -> 0 | IA10: 7 | IB10: 18 | IC10: NOR | ID10: =SUM(IB10-IA10) -> 11 | IE10: =IF(ID10>1,ID10-1,0) -> 10 | IF10: =IF(D10="STAFF",IF(IC10="NOR",IF(IE10>8.5,8.5,IE10),0),IF(IC10="NOR",IF(IE10>8,8,IE10),IF(ID10="CAMPO",IF(IC10="NOR",IF(IE10>8,8,IE10),0),IF(IC10="NOR",IF(IE10>8,8,IE10),0)))) -> 8 | IG10: =IF(IC10="NOR",IF(IE10>10,2,IF(IE10>8,(IE10-IF10),0)),0) -> 2 | IH10: =IF(IC10="NOR",IF(IE10<10,0,IF(IE10>10,(IE10-(IF10+IG10)),0)),0) -> 0 | II10: =IF(IC10="DOM",IE10,0) -> 0 | IJ10: 7 | IK10: 13 | IL10: NOR | IM10: =SUM(IK10-IJ10) -> 6 | IN10: =IF(IM10>1,IM10-1,0) -> 5 | IO10: =IF(D10="STAFF",IF(IL10="NOR",IF(IN10>8.5,8.5,IN10),0),IF(IL10="NOR",IF(IN10>8,8,IN10),IF(IM10="CAMPO",IF(IL10="NOR",IF(IN10>8,8,IN10),0),IF(IL10="NOR",IF(IN10>8,8,IN10),0)))) -> 5 | IP10: =IF(IL10="NOR",IF(IN10>10,2,IF(IN10>8,(IN10-IO10),0)),0) -> 0 | IQ10: =IF(IL10="NOR",IF(IN10<10,0,IF(IN10>10,(IN10-(IO10+IP10)),0)),0) -> 0 | IR10: =IF(IL10="DOM",IN10,0) -> 0 | IS10: 7 | IT10: 18 | IU10: NOR | IV10: =SUM(IT10-IS10) -> 11 | IW10: =IF(IV10>1,IV10-1,0) -> 10 | IX10: =IF(D10="STAFF",IF(IU10="NOR",IF(IW10>8.5,8.5,IW10),0),IF(IU10="NOR",IF(IW10>8,8,IW10),IF(IV10="CAMPO",IF(IU10="NOR",IF(IW10>8,8,IW10),0),IF(IU10="NOR",IF(IW10>8,8,IW10),0)))) -> 8 | IY10: =IF(IU10="NOR",IF(IW10>10,2,IF(IW10>8,(IW10-IX10),0)),0) -> 2 | IZ10: =IF(IU10="NOR",IF(IW10<10,0,IF(IW10>10,(IW10-(IX10+IY10)),0)),0) -> 0 | JA10: =IF(IU10="DOM",IW10,0) -> 0 | JB10: 7 | JC10: 18 | JD10: NOR | JE10: =SUM(JC10-JB10) -> 11 | JF10: =IF(JE10>1,JE10-1,0) -> 10 | JG10: =IF(D10="STAFF",IF(JD10="NOR",IF(JF10>8.5,8.5,JF10),0),IF(JD10="NOR",IF(JF10>8,8,JF10),IF(JE10="CAMPO",IF(JD10="NOR",IF(JF10>8,8,JF10),0),IF(JD10="NOR",IF(JF10>8,8,JF10),0)))) -> 8 | JH10: =IF(JD10="NOR",IF(JF10>10,2,IF(JF10>8,(JF10-JG10),0)),0) -> 2 | JI10: =IF(JD10="NOR",IF(JF10<10,0,IF(JF10>10,(JF10-(JG10+JH10)),0)),0) -> 0 | JJ10: =IF(JD10="DOM",JF10,0) -> 0 | JK10: 0 | JL10: 0 | JM10: DS | JN10: =SUM(JL10-JK10) -> 0 | JO10: =IF(JN10>1,JN10-1,0) -> 0 | JP10: =IF(D10="STAFF",IF(JM10="NOR",IF(JO10>8.5,8.5,JO10),0),IF(JM10="NOR",IF(JO10>8,8,JO10),IF(JN10="CAMPO",IF(JM10="NOR",IF(JO10>8,8,JO10),0),IF(JM10="NOR",IF(JO10>8,8,JO10),0)))) -> 0 | JQ10: =IF(JM10="NOR",IF(JO10>10,2,IF(JO10>8,(JO10-JP10),0)),0) -> 0 | JR10: =IF(JM10="NOR",IF(JO10<10,0,IF(JO10>10,(JO10-(JP10+JQ10)),0)),0) -> 0 | JS10: =IF(JM10="DOM",JO10,0) -> 0 | JT10: 7 | JU10: 18 | JV10: NOR | JW10: =SUM(JU10-JT10) -> 11 | JX10: =IF(JW10>1,JW10-1,0) -> 10 | JY10: =IF(D10="STAFF",IF(JV10="NOR",IF(JX10>8.5,8.5,JX10),0),IF(JV10="NOR",IF(JX10>8,8,JX10),IF(JW10="CAMPO",IF(JV10="NOR",IF(JX10>8,8,JX10),0),IF(JV10="NOR",IF(JX10>8,8,JX10),0)))) -> 8 | JZ10: =IF(JV10="NOR",IF(JX10>10,2,IF(JX10>8,(JX10-JY10),0)),0) -> 2 | KA10: =IF(JV10="NOR",IF(JX10<10,0,IF(JX10>10,(JX10-(JY10+JZ10)),0)),0) -> 0 | KB10: =IF(JV10="DOM",JX10,0) -> 0 | KC10: 7 | KD10: 16 | KE10: NOR | KF10: =SUM(KD10-KC10) -> 9 | KG10: =IF(KF10>1,KF10-1,0) -> 8 | KH10: =IF(D10="STAFF",IF(KE10="NOR",IF(KG10>8.5,8.5,KG10),0),IF(KE10="NOR",IF(KG10>8,8,KG10),IF(KF10="CAMPO",IF(KE10="NOR",IF(KG10>8,8,KG10),0),IF(KE10="NOR",IF(KG10>8,8,KG10),0)))) -> 8 | KI10: =IF(KE10="NOR",IF(KG10>10,2,IF(KG10>8,(KG10-KH10),0)),0) -> 0 | KJ10: =IF(KE10="NOR",IF(KG10<10,0,IF(KG10>10,(KG10-(KH10+KI10)),0)),0) -> 0 | KK10: =IF(KE10="DOM",KG10,0) -> 0 | KL10: 7 | KM10: 16 | KN10: NOR | KO10: =SUM(KM10-KL10) -> 9 | KP10: =IF(KO10>1,KO10-1,0) -> 8 | KQ10: =IF(D10="STAFF",IF(KN10="NOR",IF(KP10>8.5,8.5,KP10),0),IF(KN10="NOR",IF(KP10>8,8,KP10),IF(KO10="CAMPO",IF(KN10="NOR",IF(KP10>8,8,KP10),0),IF(KN10="NOR",IF(KP10>8,8,KP10),0)))) -> 8 | KR10: =IF(KN10="NOR",IF(KP10>10,2,IF(KP10>8,(KP10-KQ10),0)),0) -> 0 | KS10: =IF(KN10="NOR",IF(KP10<10,0,IF(KP10>10,(KP10-(KQ10+KR10)),0)),0) -> 0 | KT10: =IF(KN10="DOM",KP10,0) -> 0 | KU10: 7 | KV10: 16 | KW10: NOR | KX10: =SUM(KV10-KU10) -> 9 | KY10: =IF(KX10>1,KX10-1,0) -> 8 | KZ10: =IF(D10="STAFF",IF(KW10="NOR",IF(KY10>8.5,8.5,KY10),0),IF(KW10="NOR",IF(KY10>8,8,KY10),IF(KX10="CAMPO",IF(KW10="NOR",IF(KY10>8,8,KY10),0),IF(KW10="NOR",IF(KY10>8,8,KY10),0)))) -> 8 | LA10: =IF(KW10="NOR",IF(KY10>10,2,IF(KY10>8,(KY10-KZ10),0)),0) -> 0 | LB10: =IF(KW10="NOR",IF(KY10<10,0,IF(KY10>10,(KY10-(KZ10+LA10)),0)),0) -> 0 | LC10: =IF(KW10="DOM",KY10,0) -> 0 | LD10: 7 | LE10: 16 | LF10: NOR | LG10: =SUM(LE10-LD10) -> 9 | LH10: =IF(LG10>1,LG10-1,0) -> 8 | LI10: =IF(D10="STAFF",IF(LF10="NOR",IF(LH10>8.5,8.5,LH10),0),IF(LF10="NOR",IF(LH10>8,8,LH10),IF(LG10="CAMPO",IF(LF10="NOR",IF(LH10>8,8,LH10),0),IF(LF10="NOR",IF(LH10>8,8,LH10),0)))) -> 8 | LJ10: =IF(LF10="NOR",IF(LH10>10,2,IF(LH10>8,(LH10-LI10),0)),0) -> 0 | LK10: =IF(LF10="NOR",IF(LH10<10,0,IF(LH10>10,(LH10-(LI10+LJ10)),0)),0) -> 0 | LL10: =IF(LF10="DOM",LH10,0) -> 0 | LM10: 7 | LN10: 16 | LO10: NOR | LP10: =SUM(LN10-LM10) -> 9 | LQ10: =IF(LP10>1,LP10-1,0) -> 8 | LR10: =IF(D10="STAFF",IF(LO10="NOR",IF(LQ10>8.5,8.5,LQ10),0),IF(LO10="NOR",IF(LQ10>8,8,LQ10),IF(LP10="CAMPO",IF(LO10="NOR",IF(LQ10>8,8,LQ10),0),IF(LO10="NOR",IF(LQ10>8,8,LQ10),0)))) -> 8 | LS10: =IF(LO10="NOR",IF(LQ10>10,2,IF(LQ10>8,(LQ10-LR10),0)),0) -> 0 | LT10: =IF(LO10="NOR",IF(LQ10<10,0,IF(LQ10>10,(LQ10-(LR10+LS10)),0)),0) -> 0 | LU10: =IF(LO10="DOM",LQ10,0) -> 0 | LV10: 7 | LW10: 16 | LX10: NOR | LY10: =SUM(LW10-LV10) -> 9 | LZ10: =IF(LY10>1,LY10-1,0) -> 8 | MA10: =IF(D10="STAFF",IF(LX10="NOR",IF(LZ10>8.5,8.5,LZ10),0),IF(LX10="NOR",IF(LZ10>8,8,LZ10),IF(LY10="CAMPO",IF(LX10="NOR",IF(LZ10>8,8,LZ10),0),IF(LX10="NOR",IF(LZ10>8,8,LZ10),0)))) -> 8 | MB10: =IF(LX10="NOR",IF(LZ10>10,2,IF(LZ10>8,(LZ10-MA10),0)),0) -> 0 | MC10: =IF(LX10="NOR",IF(LZ10<10,0,IF(LZ10>10,(LZ10-(MA10+MB10)),0)),0) -> 0 | MD10: =IF(LX10="DOM",LZ10,0) -> 0 | ME10: 7 | MF10: 16 | MG10: NOR | MH10: =SUM(MF10-ME10) -> 9 | MI10: =IF(MH10>1,MH10-1,0) -> 8 | MJ10: =IF(D10="STAFF",IF(MG10="NOR",IF(MI10>8.5,8.5,MI10),0),IF(MG10="NOR",IF(MI10>8,8,MI10),IF(MH10="CAMPO",IF(MG10="NOR",IF(MI10>8,8,MI10),0),IF(MG10="NOR",IF(MI10>8,8,MI10),0)))) -> 8 | MK10: =IF(MG10="NOR",IF(MI10>10,2,IF(MI10>8,(MI10-MJ10),0)),0) -> 0 | ML10: =IF(MG10="NOR",IF(MI10<10,0,IF(MI10>10,(MI10-(MJ10+MK10)),0)),0) -> 0 | MM10: =IF(MG10="DOM",MI10,0) -> 0 | MN10: 7 | MO10: 16 | MP10: NOR | MQ10: =SUM(MO10-MN10) -> 9 | MR10: =IF(MQ10>1,MQ10-1,0) -> 8 | MS10: =IF(D10="STAFF",IF(MP10="NOR",IF(MR10>8.5,8.5,MR10),0),IF(MP10="NOR",IF(MR10>8,8,MR10),IF(MQ10="CAMPO",IF(MP10="NOR",IF(MR10>8,8,MR10),0),IF(MP10="NOR",IF(MR10>8,8,MR10),0)))) -> 8 | MT10: =IF(MP10="NOR",IF(MR10>10,2,IF(MR10>8,(MR10-MS10),0)),0) -> 0 | MU10: =IF(MP10="NOR",IF(MR10<10,0,IF(MR10>10,(MR10-(MS10+MT10)),0)),0) -> 0 | MV10: =IF(MP10="DOM",MR10,0) -> 0 | MW10: 7 | MX10: 16 | MY10: NOR | MZ10: =SUM(MX10-MW10) -> 9 | NA10: =IF(MZ10>1,MZ10-1,0) -> 8 | NB10: =IF(D10="STAFF",IF(MY10="NOR",IF(NA10>8.5,8.5,NA10),0),IF(MY10="NOR",IF(NA10>8,8,NA10),IF(MZ10="CAMPO",IF(MY10="NOR",IF(NA10>8,8,NA10),0),IF(MY10="NOR",IF(NA10>8,8,NA10),0)))) -> 8 | NC10: =IF(MY10="NOR",IF(NA10>10,2,IF(NA10>8,(NA10-NB10),0)),0) -> 0 | ND10: =IF(MY10="NOR",IF(NA10<10,0,IF(NA10>10,(NA10-(NB10+NC10)),0)),0) -> 0 | NE10: =IF(MY10="DOM",NA10,0) -> 0 | NF10: 7 | NG10: 16 | NH10: NOR | NI10: =SUM(NG10-NF10) -> 9 | NJ10: =IF(NI10>1,NI10-1,0) -> 8 | NK10: =IF(D10="STAFF",IF(NH10="NOR",IF(NJ10>8.5,8.5,NJ10),0),IF(NH10="NOR",IF(NJ10>8,8,NJ10),IF(NI10="CAMPO",IF(NH10="NOR",IF(NJ10>8,8,NJ10),0),IF(NH10="NOR",IF(NJ10>8,8,NJ10),0)))) -> 8 | NL10: =IF(NH10="NOR",IF(NJ10>10,2,IF(NJ10>8,(NJ10-NK10),0)),0) -> 0 | NM10: =IF(NH10="NOR",IF(NJ10<10,0,IF(NJ10>10,(NJ10-(NK10+NL10)),0)),0) -> 0 | NN10: =IF(NH10="DOM",NJ10,0) -> 0 | NO10: 7 | NP10: 16 | NQ10: NOR | NR10: =SUM(NP10-NO10) -> 9 | NS10: =IF(NR10>1,NR10-1,0) -> 8 | NT10: =IF(D10="STAFF",IF(NQ10="NOR",IF(NS10>8.5,8.5,NS10),0),IF(NQ10="NOR",IF(NS10>8,8,NS10),IF(NR10="CAMPO",IF(NQ10="NOR",IF(NS10>8,8,NS10),0),IF(NQ10="NOR",IF(NS10>8,8,NS10),0)))) -> 8 | NU10: =IF(NQ10="NOR",IF(NS10>10,2,IF(NS10>8,(NS10-NT10),0)),0) -> 0 | NV10: =IF(NQ10="NOR",IF(NS10<10,0,IF(NS10>10,(NS10-(NT10+NU10)),0)),0) -> 0 | NW10: =IF(NQ10="DOM",NS10,0) -> 0 | NX10: 7 | NY10: 16 | NZ10: NOR | OA10: =SUM(NY10-NX10) -> 9 | OB10: =IF(OA10>1,OA10-1,0) -> 8 | OC10: =IF(D10="STAFF",IF(NZ10="NOR",IF(OB10>8.5,8.5,OB10),0),IF(NZ10="NOR",IF(OB10>8,8,OB10),IF(OA10="CAMPO",IF(NZ10="NOR",IF(OB10>8,8,OB10),0),IF(NZ10="NOR",IF(OB10>8,8,OB10),0)))) -> 8 | OD10: =IF(NZ10="NOR",IF(OB10>10,2,IF(OB10>8,(OB10-OC10),0)),0) -> 0 | OE10: =IF(NZ10="NOR",IF(OB10<10,0,IF(OB10>10,(OB10-(OC10+OD10)),0)),0) -> 0 | OF10: =IF(NZ10="DOM",OB10,0) -> 0 | OG10: 0 | OH10: 0 | OI10: DS | OJ10: =SUM(OH10-OG10) -> 0 | OK10: =IF(OJ10>1,OJ10-1,0) -> 0 | OL10: =IF(D10="STAFF",IF(OI10="NOR",IF(OK10>8.5,8.5,OK10),0),IF(OI10="NOR",IF(OK10>8,8,OK10),IF(OJ10="CAMPO",IF(OI10="NOR",IF(OK10>8,8,OK10),0),IF(OI10="NOR",IF(OK10>8,8,OK10),0)))) -> 0 | OM10: =IF(OI10="NOR",IF(OK10>10,2,IF(OK10>8,(OK10-OL10),0)),0) -> 0 | ON10: =IF(OI10="NOR",IF(OK10<10,0,IF(OK10>10,(OK10-(OL10+OM10)),0)),0) -> 0 | OO10: =IF(OI10="DOM",OK10,0) -> 0 | OP10: 7 | OQ10: 16 | OR10: NOR | OS10: =SUM(OQ10-OP10) -> 9 | OT10: =IF(OS10>1,OS10-1,0) -> 8 | OU10: =IF(D10="STAFF",IF(OR10="NOR",IF(OT10>8.5,8.5,OT10),0),IF(OR10="NOR",IF(OT10>8,8,OT10),IF(OS10="CAMPO",IF(OR10="NOR",IF(OT10>8,8,OT10),0),IF(OR10="NOR",IF(OT10>8,8,OT10),0)))) -> 8 | OV10: =IF(OR10="NOR",IF(OT10>10,2,IF(OT10>8,(OT10-OU10),0)),0) -> 0 | OW10: =IF(OR10="NOR",IF(OT10<10,0,IF(OT10>10,(OT10-(OU10+OV10)),0)),0) -> 0 | OX10: =IF(OR10="DOM",OT10,0) -> 0 | OY10: 0 | OZ10: 0 | PA10: FE | PB10: =SUM(OZ10-OY10) -> 0 | PC10: =IF(PB10>1,PB10-1,0) -> 0 | PD10: =IF(D10="STAFF",IF(PA10="NOR",IF(PC10>8.5,8.5,PC10),0),IF(PA10="NOR",IF(PC10>8,8,PC10),IF(PB10="CAMPO",IF(PA10="NOR",IF(PC10>8,8,PC10),0),IF(PA10="NOR",IF(PC10>8,8,PC10),0)))) -> 0 | PE10: =IF(PA10="NOR",IF(PC10>10,2,IF(PC10>8,(PC10-PD10),0)),0) -> 0 | PF10: =IF(PA10="NOR",IF(PC10<10,0,IF(PC10>10,(PC10-(PD10+PE10)),0)),0) -> 0 | PG10: =IF(PA10="DOM",PC10,0) -> 0 | PH10: 7 | PI10: 16 | PJ10: NOR | PK10: =SUM(PI10-PH10) -> 9 | PL10: =IF(PK10>1,PK10-1,0) -> 8 | PM10: =IF(M10="STAFF",IF(PJ10="NOR",IF(PL10>8.5,8.5,PL10),0),IF(PJ10="NOR",IF(PL10>8,8,PL10),IF(PK10="CAMPO",IF(PJ10="NOR",IF(PL10>8,8,PL10),0),IF(PJ10="NOR",IF(PL10>8,8,PL10),0)))) -> 8 | PN10: =IF(PJ10="NOR",IF(PL10>10,2,IF(PL10>8,(PL10-PM10),0)),0) -> 0 | PO10: =IF(PJ10="NOR",IF(PL10<10,0,IF(PL10>10,(PL10-(PM10+PN10)),0)),0) -> 0 | PP10: =IF(PJ10="DOM",PL10,0) -> 0 | PR10: =COUNTIF(FG10:PP10,"NOR") -> 26 | PS10: =COUNTIF(FG10:PP10,"DS") -> 3 | PT10: =COUNTIF(FG10:PP10,"FE") -> 1 | PU10: =SUM(PR10:PT10) -> 30 | PV10: =COUNTIF(FG10:PP10,"DM") -> 0 | PY10: =COUNTIF(FG10:PP10,"SUB") -> 0 | QB10: =COUNTIF(FG10:PP10,"VA") -> 0 | QE10: =COUNTIF(FG10:PP10,"LSG") -> 0 | QH10: =COUNTIF(FG10:PP10,"LCG") -> 0 | QK10: =COUNTIF(FG10:PP10,"FA") -> 0 | QN10: =COUNTIF(J10:FF10,"FA") -> 0 | QQ10: =PU10+PV10+PY10+QB10+QE10+QH10+QK10+QN10 -> 30 | QS10: =P10+Y10++AH10+AQ10+AZ10+BI10+BR10+CA10+CJ10+CS10+DB10+DK10+DT10+EC10+EL10+EU10+FD10+FM10+FV10+GE10+GN10+GW10+HF10+HO10+HX10+IG10+IP10+IY10+JH10+JQ10+JZ10 -> 22 | QT10: =Q10+Z10++AI10+AR10+BA10+BJ10+BS10+CB10+CK10+CT10+DC10+DL10+DU10+ED10+EM10+EV10+FE10+FN10+FW10+GF10+GO10+GX10+HG10+HP10+HY10+IH10+IQ10+IZ10+JI10+JR10+KA10 -> 0 | RG10: 1
A11: =A10+1 -> 2 | B11: 48135459 | D11: PROYECTO | E11: AMADO LA ROSA PAMELA LUCERO | F11: VIGÍA | G11: 44291 | H11: 44295 | J11: 7 | K11: 18 | L11: NOR | M11: =SUM(K11-J11) -> 11 | N11: =IF(M11>1,M11-1,0) -> 10 | O11: =IF(D11="STAFF",IF(L11="NOR",IF(N11>8.5,8.5,N11),0),IF(L11="NOR",IF(N11>8,8,N11),IF(D11="CAMPO",IF(L11="NOR",IF(N11>8,8,N11),0),IF(L11="NOR",IF(N11>8,8,N11),0)))) -> 8 | P11: =IF(L11="NOR",IF(N11>10,2,IF(N11>8,(N11-O11),0)),0) -> 2 | Q11: =IF(L11="NOR",IF(N11<10,0,IF(N11>10,(N11-(O11+P11)),0)),0) -> 0 | R11: =IF(L11="DOM",N11,0) -> 0 | S11: 0 | T11: 0 | U11: DS | V11: =SUM(T11-S11) -> 0 | W11: =IF(V11>1,V11-1,0) -> 0 | X11: =IF(D11="STAFF",IF(U11="NOR",IF(W11>8.5,8.5,W11),0),IF(U11="NOR",IF(W11>8,8,W11),IF(M11="CAMPO",IF(U11="NOR",IF(W11>8,8,W11),0),IF(U11="NOR",IF(W11>8,8,W11),0)))) -> 0 | Y11: =IF(U11="NOR",IF(W11>10,2,IF(W11>8,(W11-X11),0)),0) -> 0 | Z11: =IF(U11="NOR",IF(W11<10,0,IF(W11>10,(W11-(X11+Y11)),0)),0) -> 0 | AA11: =IF(U11="DOM",W11,0) -> 0 | AB11: 7 | AC11: 18 | AD11: NOR | AE11: =SUM(AC11-AB11) -> 11 | AF11: =IF(AE11>1,AE11-1,0) -> 10 | AG11: =IF(D11="STAFF",IF(AD11="NOR",IF(AF11>8.5,8.5,AF11),0),IF(AD11="NOR",IF(AF11>8,8,AF11),IF(AE11="CAMPO",IF(AD11="NOR",IF(AF11>8,8,AF11),0),IF(AD11="NOR",IF(AF11>8,8,AF11),0)))) -> 8 | AH11: =IF(AD11="NOR",IF(AF11>10,2,IF(AF11>8,(AF11-AG11),0)),0) -> 2 | AI11: =IF(AD11="NOR",IF(AF11<10,0,IF(AF11>10,(AF11-(AG11+AH11)),0)),0) -> 0 | AJ11: =IF(AD11="DOM",AF11,0) -> 0 | AK11: 7 | AL11: 18 | AM11: NOR | AN11: =SUM(AL11-AK11) -> 11 | AO11: =IF(AN11>1,AN11-1,0) -> 10 | AP11: =IF(D11="PROYECTO",IF(AM11="NOR",IF(AO11>8,8,AO11),0),IF(AM11="NOR",IF(AO11>8,8,AO11),0)) -> 8 | AQ11: =IF(AM11="NOR",IF(AO11>10,2,IF(AO11>8,(AO11-AP11),0)),0) -> 2 | AR11: =IF(AM11="NOR",IF(AO11<10,0,IF(AO11>10,(AO11-(AP11+AQ11)),0)),0) -> 0 | AS11: =IF(AM11="DOM",AO11,0) -> 0 | AT11: 7 | AU11: 18 | AV11: NOR | AW11: =SUM(AU11-AT11) -> 11 | AX11: =IF(AW11>1,AW11-1,0) -> 10 | AY11: =IF(AO11="PROYECTO",IF(AV11="NOR",IF(AX11>8,8,AX11),0),IF(AV11="NOR",IF(AX11>8,8,AX11),0)) -> 8 | AZ11: =IF(AV11="NOR",IF(AX11>10,2,IF(AX11>8,(AX11-AY11),0)),0) -> 2 | BA11: =IF(AV11="NOR",IF(AX11<10,0,IF(AX11>10,(AX11-(AY11+AZ11)),0)),0) -> 0 | BB11: =IF(AV11="DOM",AX11,0) -> 0 | BC11: 7 | BD11: 18 | BE11: NOR | BF11: =SUM(BD11-BC11) -> 11 | BG11: =IF(BF11>1,BF11-1,0) -> 10 | BH11: =IF(D11="STAFF",IF(BE11="NOR",IF(BG11>8.5,8.5,BG11),0),IF(BE11="NOR",IF(BG11>8,8,BG11),IF(BF11="CAMPO",IF(BE11="NOR",IF(BG11>8,8,BG11),0),IF(BE11="NOR",IF(BG11>8,8,BG11),0)))) -> 8 | BI11: =IF(BE11="NOR",IF(BG11>10,2,IF(BG11>8,(BG11-BH11),0)),0) -> 2 | BJ11: =IF(BE11="NOR",IF(BG11<10,0,IF(BG11>10,(BG11-(BH11+BI11)),0)),0) -> 0 | BK11: =IF(BE11="DOM",BG11,0) -> 0 | BL11: 7 | BM11: 18 | BN11: NOR | BO11: =SUM(BM11-BL11) -> 11 | BP11: =IF(BO11>1,BO11-1,0) -> 10 | BQ11: =IF(D11="STAFF",IF(BN11="NOR",IF(BP11>8.5,8.5,BP11),0),IF(BN11="NOR",IF(BP11>8,8,BP11),IF(BO11="CAMPO",IF(BN11="NOR",IF(BP11>8,8,BP11),0),IF(BN11="NOR",IF(BP11>8,8,BP11),0)))) -> 8 | BR11: =IF(BN11="NOR",IF(BP11>10,2,IF(BP11>8,(BP11-BQ11),0)),0) -> 2 | BS11: =IF(BN11="NOR",IF(BP11<10,0,IF(BP11>10,(BP11-(BQ11+BR11)),0)),0) -> 0 | BT11: =IF(BN11="DOM",BP11,0) -> 0 | BU11: 7 | BV11: 18 | BW11: NOR | BX11: =SUM(BV11-BU11) -> 11 | BY11: =IF(BX11>1,BX11-1,0) -> 10 | BZ11: =IF(D11="STAFF",IF(BW11="NOR",IF(BY11>8.5,8.5,BY11),0),IF(BW11="NOR",IF(BY11>8,8,BY11),IF(BX11="CAMPO",IF(BW11="NOR",IF(BY11>8,8,BY11),0),IF(BW11="NOR",IF(BY11>8,8,BY11),0)))) -> 8 | CA11: =IF(BW11="NOR",IF(BY11>10,2,IF(BY11>8,(BY11-BZ11),0)),0) -> 2 | CB11: =IF(BW11="NOR",IF(BY11<10,0,IF(BY11>10,(BY11-(BZ11+CA11)),0)),0) -> 0 | CC11: =IF(BW11="DOM",BY11,0) -> 0 | CD11: 0 | CE11: 0 | CF11: DS | CG11: =SUM(CE11-CD11) -> 0 | CH11: =IF(CG11>1,CG11-1,0) -> 0 | CI11: =IF(D11="STAFF",IF(CF11="NOR",IF(CH11>8.5,8.5,CH11),0),IF(CF11="NOR",IF(CH11>8,8,CH11),IF(CG11="CAMPO",IF(CF11="NOR",IF(CH11>8,8,CH11),0),IF(CF11="NOR",IF(CH11>8,8,CH11),0)))) -> 0 | CJ11: =IF(CF11="NOR",IF(CH11>10,2,IF(CH11>8,(CH11-CI11),0)),0) -> 0 | CK11: =IF(CF11="NOR",IF(CH11<10,0,IF(CH11>10,(CH11-(CI11+CJ11)),0)),0) -> 0 | CL11: =IF(CF11="DOM",CH11,0) -> 0 | CM11: 7 | CN11: 18 | CO11: NOR | CP11: =SUM(CN11-CM11) -> 11 | CQ11: =IF(CP11>1,CP11-1,0) -> 10 | CR11: =IF(D11="STAFF",IF(CO11="NOR",IF(CQ11>8.5,8.5,CQ11),0),IF(CO11="NOR",IF(CQ11>8,8,CQ11),IF(CP11="CAMPO",IF(CO11="NOR",IF(CQ11>8,8,CQ11),0),IF(CO11="NOR",IF(CQ11>8,8,CQ11),0)))) -> 8 | CS11: =IF(CO11="NOR",IF(CQ11>10,2,IF(CQ11>8,(CQ11-CR11),0)),0) -> 2 | CT11: =IF(CO11="NOR",IF(CQ11<10,0,IF(CQ11>10,(CQ11-(CR11+CS11)),0)),0) -> 0 | CU11: =IF(CO11="DOM",CQ11,0) -> 0 | CV11: 7 | CW11: 18 | CX11: NOR | CY11: =SUM(CW11-CV11) -> 11 | CZ11: =IF(CY11>1,CY11-1,0) -> 10 | DA11: =IF(CQ11="PROYECTO",IF(CX11="NOR",IF(CZ11>8,8,CZ11),0),IF(CX11="NOR",IF(CZ11>8,8,CZ11),0)) -> 8 | DB11: =IF(CX11="NOR",IF(CZ11>10,2,IF(CZ11>8,(CZ11-DA11),0)),0) -> 2 | DC11: =IF(CX11="NOR",IF(CZ11<10,0,IF(CZ11>10,(CZ11-(DA11+DB11)),0)),0) -> 0 | DD11: =IF(CX11="DOM",CZ11,0) -> 0 | DE11: 7 | DF11: 18 | DG11: NOR | DH11: =SUM(DF11-DE11) -> 11 | DI11: =IF(DH11>1,DH11-1,0) -> 10 | DJ11: =IF(CZ11="PROYECTO",IF(DG11="NOR",IF(DI11>8,8,DI11),0),IF(DG11="NOR",IF(DI11>8,8,DI11),0)) -> 8 | DK11: =IF(DG11="NOR",IF(DI11>10,2,IF(DI11>8,(DI11-DJ11),0)),0) -> 2 | DL11: =IF(DG11="NOR",IF(DI11<10,0,IF(DI11>10,(DI11-(DJ11+DK11)),0)),0) -> 0 | DM11: =IF(DG11="DOM",DI11,0) -> 0 | DN11: 7 | DO11: 18 | DP11: NOR | DQ11: =SUM(DO11-DN11) -> 11 | DR11: =IF(DQ11>1,DQ11-1,0) -> 10 | DS11: =IF(D11="STAFF",IF(DP11="NOR",IF(DR11>8.5,8.5,DR11),0),IF(DP11="NOR",IF(DR11>8,8,DR11),IF(DQ11="CAMPO",IF(DP11="NOR",IF(DR11>8,8,DR11),0),IF(DP11="NOR",IF(DR11>8,8,DR11),0)))) -> 8 | DT11: =IF(DP11="NOR",IF(DR11>10,2,IF(DR11>8,(DR11-DS11),0)),0) -> 2 | DU11: =IF(DP11="NOR",IF(DR11<10,0,IF(DR11>10,(DR11-(DS11+DT11)),0)),0) -> 0 | DV11: =IF(DP11="DOM",DR11,0) -> 0 | DW11: 7 | DX11: 18 | DY11: NOR | DZ11: =SUM(DX11-DW11) -> 11 | EA11: =IF(DZ11>1,DZ11-1,0) -> 10 | EB11: =IF(D11="STAFF",IF(DY11="NOR",IF(EA11>8.5,8.5,EA11),0),IF(DY11="NOR",IF(EA11>8,8,EA11),IF(DZ11="CAMPO",IF(DY11="NOR",IF(EA11>8,8,EA11),0),IF(DY11="NOR",IF(EA11>8,8,EA11),0)))) -> 8 | EC11: =IF(DY11="NOR",IF(EA11>10,2,IF(EA11>8,(EA11-EB11),0)),0) -> 2 | ED11: =IF(DY11="NOR",IF(EA11<10,0,IF(EA11>10,(EA11-(EB11+EC11)),0)),0) -> 0 | EE11: =IF(DY11="DOM",EA11,0) -> 0 | EF11: 7 | EG11: 18 | EH11: NOR | EI11: =SUM(EG11-EF11) -> 11 | EJ11: =IF(EI11>1,EI11-1,0) -> 10 | EK11: =IF(D11="STAFF",IF(EH11="NOR",IF(EJ11>8.5,8.5,EJ11),0),IF(EH11="NOR",IF(EJ11>8,8,EJ11),IF(EI11="CAMPO",IF(EH11="NOR",IF(EJ11>8,8,EJ11),0),IF(EH11="NOR",IF(EJ11>8,8,EJ11),0)))) -> 8 | EL11: =IF(EH11="NOR",IF(EJ11>10,2,IF(EJ11>8,(EJ11-EK11),0)),0) -> 2 | EM11: =IF(EH11="NOR",IF(EJ11<10,0,IF(EJ11>10,(EJ11-(EK11+EL11)),0)),0) -> 0 | EN11: =IF(EH11="DOM",EJ11,0) -> 0 | EO11: 0 | EP11: 0 | EQ11: DS | ER11: =SUM(EP11-EO11) -> 0 | ES11: =IF(ER11>1,ER11-1,0) -> 0 | ET11: =IF(D11="STAFF",IF(EQ11="NOR",IF(ES11>8.5,8.5,ES11),0),IF(EQ11="NOR",IF(ES11>8,8,ES11),IF(ER11="CAMPO",IF(EQ11="NOR",IF(ES11>8,8,ES11),0),IF(EQ11="NOR",IF(ES11>8,8,ES11),0)))) -> 0 | EU11: =IF(EQ11="NOR",IF(ES11>10,2,IF(ES11>8,(ES11-ET11),0)),0) -> 0 | EV11: =IF(EQ11="NOR",IF(ES11<10,0,IF(ES11>10,(ES11-(ET11+EU11)),0)),0) -> 0 | EW11: =IF(EQ11="DOM",ES11,0) -> 0 | EX11: 7 | EY11: 18 | EZ11: NOR | FA11: =SUM(EY11-EX11) -> 11 | FB11: =IF(FA11>1,FA11-1,0) -> 10 | FC11: =IF(D11="STAFF",IF(EZ11="NOR",IF(FB11>8.5,8.5,FB11),0),IF(EZ11="NOR",IF(FB11>8,8,FB11),IF(FA11="CAMPO",IF(EZ11="NOR",IF(FB11>8,8,FB11),0),IF(EZ11="NOR",IF(FB11>8,8,FB11),0)))) -> 8 | FD11: =IF(EZ11="NOR",IF(FB11>10,2,IF(FB11>8,(FB11-FC11),0)),0) -> 2 | FE11: =IF(EZ11="NOR",IF(FB11<10,0,IF(FB11>10,(FB11-(FC11+FD11)),0)),0) -> 0 | FF11: =IF(EZ11="DOM",FB11,0) -> 0 | FG11: 7 | FH11: 18 | FI11: NOR | FJ11: =SUM(FH11-FG11) -> 11 | FK11: =IF(FJ11>1,FJ11-1,0) -> 10 | FL11: =IF(D11="STAFF",IF(FI11="NOR",IF(FK11>8.5,8.5,FK11),0),IF(FI11="NOR",IF(FK11>8,8,FK11),IF(FJ11="CAMPO",IF(FI11="NOR",IF(FK11>8,8,FK11),0),IF(FI11="NOR",IF(FK11>8,8,FK11),0)))) -> 8 | FM11: =IF(FI11="NOR",IF(FK11>10,2,IF(FK11>8,(FK11-FL11),0)),0) -> 2 | FN11: =IF(FI11="NOR",IF(FK11<10,0,IF(FK11>10,(FK11-(FL11+FM11)),0)),0) -> 0 | FO11: =IF(FI11="DOM",FK11,0) -> 0 | FP11: 7 | FQ11: 18 | FR11: NOR | FS11: =SUM(FQ11-FP11) -> 11 | FT11: =IF(FS11>1,FS11-1,0) -> 10 | FU11: =IF(FK11="PROYECTO",IF(FR11="NOR",IF(FT11>8,8,FT11),0),IF(FR11="NOR",IF(FT11>8,8,FT11),0)) -> 8 | FV11: =IF(FR11="NOR",IF(FT11>10,2,IF(FT11>8,(FT11-FU11),0)),0) -> 2 | FW11: =IF(FR11="NOR",IF(FT11<10,0,IF(FT11>10,(FT11-(FU11+FV11)),0)),0) -> 0 | FX11: =IF(FR11="DOM",FT11,0) -> 0 | FY11: 7 | FZ11: 18 | GA11: NOR | GB11: =SUM(FZ11-FY11) -> 11 | GC11: =IF(GB11>1,GB11-1,0) -> 10 | GD11: =IF(D11="STAFF",IF(GA11="NOR",IF(GC11>8.5,8.5,GC11),0),IF(GA11="NOR",IF(GC11>8,8,GC11),IF(GB11="CAMPO",IF(GA11="NOR",IF(GC11>8,8,GC11),0),IF(GA11="NOR",IF(GC11>8,8,GC11),0)))) -> 8 | GE11: =IF(GA11="NOR",IF(GC11>10,2,IF(GC11>8,(GC11-GD11),0)),0) -> 2 | GF11: =IF(GA11="NOR",IF(GC11<10,0,IF(GC11>10,(GC11-(GD11+GE11)),0)),0) -> 0 | GG11: =IF(GA11="DOM",GC11,0) -> 0 | GH11: 7 | GI11: 18 | GJ11: NOR | GK11: =SUM(GI11-GH11) -> 11 | GL11: =IF(GK11>1,GK11-1,0) -> 10 | GM11: =IF(D11="STAFF",IF(GJ11="NOR",IF(GL11>8.5,8.5,GL11),0),IF(GJ11="NOR",IF(GL11>8,8,GL11),IF(GK11="CAMPO",IF(GJ11="NOR",IF(GL11>8,8,GL11),0),IF(GJ11="NOR",IF(GL11>8,8,GL11),0)))) -> 8 | GN11: =IF(GJ11="NOR",IF(GL11>10,2,IF(GL11>8,(GL11-GM11),0)),0) -> 2 | GO11: =IF(GJ11="NOR",IF(GL11<10,0,IF(GL11>10,(GL11-(GM11+GN11)),0)),0) -> 0 | GP11: =IF(GJ11="DOM",GL11,0) -> 0 | GQ11: 9 | GR11: 18 | GS11: NOR | GT11: =SUM(GR11-GQ11) -> 9 | GU11: =IF(GT11>1,GT11-1,0) -> 8 | GV11: =IF(D11="STAFF",IF(GS11="NOR",IF(GU11>8.5,8.5,GU11),0),IF(GS11="NOR",IF(GU11>8,8,GU11),IF(GT11="CAMPO",IF(GS11="NOR",IF(GU11>8,8,GU11),0),IF(GS11="NOR",IF(GU11>8,8,GU11),0)))) -> 8 | GW11: =IF(GS11="NOR",IF(GU11>10,2,IF(GU11>8,(GU11-GV11),0)),0) -> 0 | GX11: =IF(GS11="NOR",IF(GU11<10,0,IF(GU11>10,(GU11-(GV11+GW11)),0)),0) -> 0 | GY11: =IF(GS11="DOM",GU11,0) -> 0 | GZ11: 0 | HA11: 0 | HB11: DS | HC11: =SUM(HA11-GZ11) -> 0 | HD11: =IF(HC11>1,HC11-1,0) -> 0 | HE11: =IF(D11="STAFF",IF(HB11="NOR",IF(HD11>8.5,8.5,HD11),0),IF(HB11="NOR",IF(HD11>8,8,HD11),IF(HC11="CAMPO",IF(HB11="NOR",IF(HD11>8,8,HD11),0),IF(HB11="NOR",IF(HD11>8,8,HD11),0)))) -> 0 | HF11: =IF(HB11="NOR",IF(HD11>10,2,IF(HD11>8,(HD11-HE11),0)),0) -> 0 | HG11: =IF(HB11="NOR",IF(HD11<10,0,IF(HD11>10,(HD11-(HE11+HF11)),0)),0) -> 0 | HH11: =IF(HB11="DOM",HD11,0) -> 0 | HI11: 7 | HJ11: 18 | HK11: NOR | HL11: =SUM(HJ11-HI11) -> 11 | HM11: =IF(HL11>1,HL11-1,0) -> 10 | HN11: =IF(D11="STAFF",IF(HK11="NOR",IF(HM11>8.5,8.5,HM11),0),IF(HK11="NOR",IF(HM11>8,8,HM11),IF(HL11="CAMPO",IF(HK11="NOR",IF(HM11>8,8,HM11),0),IF(HK11="NOR",IF(HM11>8,8,HM11),0)))) -> 8 | HO11: =IF(HK11="NOR",IF(HM11>10,2,IF(HM11>8,(HM11-HN11),0)),0) -> 2 | HP11: =IF(HK11="NOR",IF(HM11<10,0,IF(HM11>10,(HM11-(HN11+HO11)),0)),0) -> 0 | HQ11: =IF(HK11="DOM",HM11,0) -> 0 | HR11: 7 | HS11: 18 | HT11: NOR | HU11: =SUM(HS11-HR11) -> 11 | HV11: =IF(HU11>1,HU11-1,0) -> 10 | HW11: =IF(D11="STAFF",IF(HT11="NOR",IF(HV11>8.5,8.5,HV11),0),IF(HT11="NOR",IF(HV11>8,8,HV11),IF(HU11="CAMPO",IF(HT11="NOR",IF(HV11>8,8,HV11),0),IF(HT11="NOR",IF(HV11>8,8,HV11),0)))) -> 8 | HX11: =IF(HT11="NOR",IF(HV11>10,2,IF(HV11>8,(HV11-HW11),0)),0) -> 2 | HY11: =IF(HT11="NOR",IF(HV11<10,0,IF(HV11>10,(HV11-(HW11+HX11)),0)),0) -> 0 | HZ11: =IF(HT11="DOM",HV11,0) -> 0 | IA11: 7 | IB11: 14 | IC11: NOR | ID11: =SUM(IB11-IA11) -> 7 | IE11: =IF(ID11>1,ID11-1,0) -> 6 | IF11: =IF(D11="STAFF",IF(IC11="NOR",IF(IE11>8.5,8.5,IE11),0),IF(IC11="NOR",IF(IE11>8,8,IE11),IF(ID11="CAMPO",IF(IC11="NOR",IF(IE11>8,8,IE11),0),IF(IC11="NOR",IF(IE11>8,8,IE11),0)))) -> 6 | IG11: =IF(IC11="NOR",IF(IE11>10,2,IF(IE11>8,(IE11-IF11),0)),0) -> 0 | IH11: =IF(IC11="NOR",IF(IE11<10,0,IF(IE11>10,(IE11-(IF11+IG11)),0)),0) -> 0 | II11: =IF(IC11="DOM",IE11,0) -> 0 | IJ11: 7 | IK11: 18 | IL11: NOR | IM11: =SUM(IK11-IJ11) -> 11 | IN11: =IF(IM11>1,IM11-1,0) -> 10 | IO11: =IF(D11="STAFF",IF(IL11="NOR",IF(IN11>8.5,8.5,IN11),0),IF(IL11="NOR",IF(IN11>8,8,IN11),IF(IM11="CAMPO",IF(IL11="NOR",IF(IN11>8,8,IN11),0),IF(IL11="NOR",IF(IN11>8,8,IN11),0)))) -> 8 | IP11: =IF(IL11="NOR",IF(IN11>10,2,IF(IN11>8,(IN11-IO11),0)),0) -> 2 | IQ11: =IF(IL11="NOR",IF(IN11<10,0,IF(IN11>10,(IN11-(IO11+IP11)),0)),0) -> 0 | IR11: =IF(IL11="DOM",IN11,0) -> 0 | IS11: 7 | IT11: 18 | IU11: NOR | IV11: =SUM(IT11-IS11) -> 11 | IW11: =IF(IV11>1,IV11-1,0) -> 10 | IX11: =IF(D11="STAFF",IF(IU11="NOR",IF(IW11>8.5,8.5,IW11),0),IF(IU11="NOR",IF(IW11>8,8,IW11),IF(IV11="CAMPO",IF(IU11="NOR",IF(IW11>8,8,IW11),0),IF(IU11="NOR",IF(IW11>8,8,IW11),0)))) -> 8 | IY11: =IF(IU11="NOR",IF(IW11>10,2,IF(IW11>8,(IW11-IX11),0)),0) -> 2 | IZ11: =IF(IU11="NOR",IF(IW11<10,0,IF(IW11>10,(IW11-(IX11+IY11)),0)),0) -> 0 | JA11: =IF(IU11="DOM",IW11,0) -> 0 | JB11: 7 | JC11: 18 | JD11: NOR | JE11: =SUM(JC11-JB11) -> 11 | JF11: =IF(JE11>1,JE11-1,0) -> 10 | JG11: =IF(D11="STAFF",IF(JD11="NOR",IF(JF11>8.5,8.5,JF11),0),IF(JD11="NOR",IF(JF11>8,8,JF11),IF(JE11="CAMPO",IF(JD11="NOR",IF(JF11>8,8,JF11),0),IF(JD11="NOR",IF(JF11>8,8,JF11),0)))) -> 8 | JH11: =IF(JD11="NOR",IF(JF11>10,2,IF(JF11>8,(JF11-JG11),0)),0) -> 2 | JI11: =IF(JD11="NOR",IF(JF11<10,0,IF(JF11>10,(JF11-(JG11+JH11)),0)),0) -> 0 | JJ11: =IF(JD11="DOM",JF11,0) -> 0 | JK11: 0 | JL11: 0 | JM11: DS | JN11: =SUM(JL11-JK11) -> 0 | JO11: =IF(JN11>1,JN11-1,0) -> 0 | JP11: =IF(D11="STAFF",IF(JM11="NOR",IF(JO11>8.5,8.5,JO11),0),IF(JM11="NOR",IF(JO11>8,8,JO11),IF(JN11="CAMPO",IF(JM11="NOR",IF(JO11>8,8,JO11),0),IF(JM11="NOR",IF(JO11>8,8,JO11),0)))) -> 0 | JQ11: =IF(JM11="NOR",IF(JO11>10,2,IF(JO11>8,(JO11-JP11),0)),0) -> 0 | JR11: =IF(JM11="NOR",IF(JO11<10,0,IF(JO11>10,(JO11-(JP11+JQ11)),0)),0) -> 0 | JS11: =IF(JM11="DOM",JO11,0) -> 0 | JT11: 7 | JU11: 19 | JV11: NOR | JW11: =SUM(JU11-JT11) -> 12 | JX11: =IF(JW11>1,JW11-1,0) -> 11 | JY11: =IF(D11="STAFF",IF(JV11="NOR",IF(JX11>8.5,8.5,JX11),0),IF(JV11="NOR",IF(JX11>8,8,JX11),IF(JW11="CAMPO",IF(JV11="NOR",IF(JX11>8,8,JX11),0),IF(JV11="NOR",IF(JX11>8,8,JX11),0)))) -> 8 | JZ11: =IF(JV11="NOR",IF(JX11>10,2,IF(JX11>8,(JX11-JY11),0)),0) -> 2 | KA11: =IF(JV11="NOR",IF(JX11<10,0,IF(JX11>10,(JX11-(JY11+JZ11)),0)),0) -> 1 | KB11: =IF(JV11="DOM",JX11,0) -> 0 | KC11: 7 | KD11: 16 | KE11: NOR | KF11: =SUM(KD11-KC11) -> 9 | KG11: =IF(KF11>1,KF11-1,0) -> 8 | KH11: =IF(D11="STAFF",IF(KE11="NOR",IF(KG11>8.5,8.5,KG11),0),IF(KE11="NOR",IF(KG11>8,8,KG11),IF(KF11="CAMPO",IF(KE11="NOR",IF(KG11>8,8,KG11),0),IF(KE11="NOR",IF(KG11>8,8,KG11),0)))) -> 8 | KI11: =IF(KE11="NOR",IF(KG11>10,2,IF(KG11>8,(KG11-KH11),0)),0) -> 0 | KJ11: =IF(KE11="NOR",IF(KG11<10,0,IF(KG11>10,(KG11-(KH11+KI11)),0)),0) -> 0 | KK11: =IF(KE11="DOM",KG11,0) -> 0 | KL11: 7 | KM11: 16 | KN11: NOR | KO11: =SUM(KM11-KL11) -> 9 | KP11: =IF(KO11>1,KO11-1,0) -> 8 | KQ11: =IF(D11="STAFF",IF(KN11="NOR",IF(KP11>8.5,8.5,KP11),0),IF(KN11="NOR",IF(KP11>8,8,KP11),IF(KO11="CAMPO",IF(KN11="NOR",IF(KP11>8,8,KP11),0),IF(KN11="NOR",IF(KP11>8,8,KP11),0)))) -> 8 | KR11: =IF(KN11="NOR",IF(KP11>10,2,IF(KP11>8,(KP11-KQ11),0)),0) -> 0 | KS11: =IF(KN11="NOR",IF(KP11<10,0,IF(KP11>10,(KP11-(KQ11+KR11)),0)),0) -> 0 | KT11: =IF(KN11="DOM",KP11,0) -> 0 | KU11: 7 | KV11: 16 | KW11: NOR | KX11: =SUM(KV11-KU11) -> 9 | KY11: =IF(KX11>1,KX11-1,0) -> 8 | KZ11: =IF(D11="STAFF",IF(KW11="NOR",IF(KY11>8.5,8.5,KY11),0),IF(KW11="NOR",IF(KY11>8,8,KY11),IF(KX11="CAMPO",IF(KW11="NOR",IF(KY11>8,8,KY11),0),IF(KW11="NOR",IF(KY11>8,8,KY11),0)))) -> 8 | LA11: =IF(KW11="NOR",IF(KY11>10,2,IF(KY11>8,(KY11-KZ11),0)),0) -> 0 | LB11: =IF(KW11="NOR",IF(KY11<10,0,IF(KY11>10,(KY11-(KZ11+LA11)),0)),0) -> 0 | LC11: =IF(KW11="DOM",KY11,0) -> 0 | LD11: 7 | LE11: 16 | LF11: NOR | LG11: =SUM(LE11-LD11) -> 9 | LH11: =IF(LG11>1,LG11-1,0) -> 8 | LI11: =IF(D11="STAFF",IF(LF11="NOR",IF(LH11>8.5,8.5,LH11),0),IF(LF11="NOR",IF(LH11>8,8,LH11),IF(LG11="CAMPO",IF(LF11="NOR",IF(LH11>8,8,LH11),0),IF(LF11="NOR",IF(LH11>8,8,LH11),0)))) -> 8 | LJ11: =IF(LF11="NOR",IF(LH11>10,2,IF(LH11>8,(LH11-LI11),0)),0) -> 0 | LK11: =IF(LF11="NOR",IF(LH11<10,0,IF(LH11>10,(LH11-(LI11+LJ11)),0)),0) -> 0 | LL11: =IF(LF11="DOM",LH11,0) -> 0 | LM11: 7 | LN11: 16 | LO11: NOR | LP11: =SUM(LN11-LM11) -> 9 | LQ11: =IF(LP11>1,LP11-1,0) -> 8 | LR11: =IF(D11="STAFF",IF(LO11="NOR",IF(LQ11>8.5,8.5,LQ11),0),IF(LO11="NOR",IF(LQ11>8,8,LQ11),IF(LP11="CAMPO",IF(LO11="NOR",IF(LQ11>8,8,LQ11),0),IF(LO11="NOR",IF(LQ11>8,8,LQ11),0)))) -> 8 | LS11: =IF(LO11="NOR",IF(LQ11>10,2,IF(LQ11>8,(LQ11-LR11),0)),0) -> 0 | LT11: =IF(LO11="NOR",IF(LQ11<10,0,IF(LQ11>10,(LQ11-(LR11+LS11)),0)),0) -> 0 | LU11: =IF(LO11="DOM",LQ11,0) -> 0 | LV11: 7 | LW11: 16 | LX11: NOR | LY11: =SUM(LW11-LV11) -> 9 | LZ11: =IF(LY11>1,LY11-1,0) -> 8 | MA11: =IF(D11="STAFF",IF(LX11="NOR",IF(LZ11>8.5,8.5,LZ11),0),IF(LX11="NOR",IF(LZ11>8,8,LZ11),IF(LY11="CAMPO",IF(LX11="NOR",IF(LZ11>8,8,LZ11),0),IF(LX11="NOR",IF(LZ11>8,8,LZ11),0)))) -> 8 | MB11: =IF(LX11="NOR",IF(LZ11>10,2,IF(LZ11>8,(LZ11-MA11),0)),0) -> 0 | MC11: =IF(LX11="NOR",IF(LZ11<10,0,IF(LZ11>10,(LZ11-(MA11+MB11)),0)),0) -> 0 | MD11: =IF(LX11="DOM",LZ11,0) -> 0 | ME11: 7 | MF11: 16 | MG11: NOR | MH11: =SUM(MF11-ME11) -> 9 | MI11: =IF(MH11>1,MH11-1,0) -> 8 | MJ11: =IF(D11="STAFF",IF(MG11="NOR",IF(MI11>8.5,8.5,MI11),0),IF(MG11="NOR",IF(MI11>8,8,MI11),IF(MH11="CAMPO",IF(MG11="NOR",IF(MI11>8,8,MI11),0),IF(MG11="NOR",IF(MI11>8,8,MI11),0)))) -> 8 | MK11: =IF(MG11="NOR",IF(MI11>10,2,IF(MI11>8,(MI11-MJ11),0)),0) -> 0 | ML11: =IF(MG11="NOR",IF(MI11<10,0,IF(MI11>10,(MI11-(MJ11+MK11)),0)),0) -> 0 | MM11: =IF(MG11="DOM",MI11,0) -> 0 | MN11: 7 | MO11: 16 | MP11: NOR | MQ11: =SUM(MO11-MN11) -> 9 | MR11: =IF(MQ11>1,MQ11-1,0) -> 8 | MS11: =IF(D11="STAFF",IF(MP11="NOR",IF(MR11>8.5,8.5,MR11),0),IF(MP11="NOR",IF(MR11>8,8,MR11),IF(MQ11="CAMPO",IF(MP11="NOR",IF(MR11>8,8,MR11),0),IF(MP11="NOR",IF(MR11>8,8,MR11),0)))) -> 8 | MT11: =IF(MP11="NOR",IF(MR11>10,2,IF(MR11>8,(MR11-MS11),0)),0) -> 0 | MU11: =IF(MP11="NOR",IF(MR11<10,0,IF(MR11>10,(MR11-(MS11+MT11)),0)),0) -> 0 | MV11: =IF(MP11="DOM",MR11,0) -> 0 | MW11: 7 | MX11: 16 | MY11: NOR | MZ11: =SUM(MX11-MW11) -> 9 | NA11: =IF(MZ11>1,MZ11-1,0) -> 8 | NB11: =IF(D11="STAFF",IF(MY11="NOR",IF(NA11>8.5,8.5,NA11),0),IF(MY11="NOR",IF(NA11>8,8,NA11),IF(MZ11="CAMPO",IF(MY11="NOR",IF(NA11>8,8,NA11),0),IF(MY11="NOR",IF(NA11>8,8,NA11),0)))) -> 8 | NC11: =IF(MY11="NOR",IF(NA11>10,2,IF(NA11>8,(NA11-NB11),0)),0) -> 0 | ND11: =IF(MY11="NOR",IF(NA11<10,0,IF(NA11>10,(NA11-(NB11+NC11)),0)),0) -> 0 | NE11: =IF(MY11="DOM",NA11,0) -> 0 | NF11: 7 | NG11: 16 | NH11: NOR | NI11: =SUM(NG11-NF11) -> 9 | NJ11: =IF(NI11>1,NI11-1,0) -> 8 | NK11: =IF(D11="STAFF",IF(NH11="NOR",IF(NJ11>8.5,8.5,NJ11),0),IF(NH11="NOR",IF(NJ11>8,8,NJ11),IF(NI11="CAMPO",IF(NH11="NOR",IF(NJ11>8,8,NJ11),0),IF(NH11="NOR",IF(NJ11>8,8,NJ11),0)))) -> 8 | NL11: =IF(NH11="NOR",IF(NJ11>10,2,IF(NJ11>8,(NJ11-NK11),0)),0) -> 0 | NM11: =IF(NH11="NOR",IF(NJ11<10,0,IF(NJ11>10,(NJ11-(NK11+NL11)),0)),0) -> 0 | NN11: =IF(NH11="DOM",NJ11,0) -> 0 | NO11: 7 | NP11: 16 | NQ11: NOR | NR11: =SUM(NP11-NO11) -> 9 | NS11: =IF(NR11>1,NR11-1,0) -> 8 | NT11: =IF(D11="STAFF",IF(NQ11="NOR",IF(NS11>8.5,8.5,NS11),0),IF(NQ11="NOR",IF(NS11>8,8,NS11),IF(NR11="CAMPO",IF(NQ11="NOR",IF(NS11>8,8,NS11),0),IF(NQ11="NOR",IF(NS11>8,8,NS11),0)))) -> 8 | NU11: =IF(NQ11="NOR",IF(NS11>10,2,IF(NS11>8,(NS11-NT11),0)),0) -> 0 | NV11: =IF(NQ11="NOR",IF(NS11<10,0,IF(NS11>10,(NS11-(NT11+NU11)),0)),0) -> 0 | NW11: =IF(NQ11="DOM",NS11,0) -> 0 | NX11: 7 | NY11: 16 | NZ11: NOR | OA11: =SUM(NY11-NX11) -> 9 | OB11: =IF(OA11>1,OA11-1,0) -> 8 | OC11: =IF(D11="STAFF",IF(NZ11="NOR",IF(OB11>8.5,8.5,OB11),0),IF(NZ11="NOR",IF(OB11>8,8,OB11),IF(OA11="CAMPO",IF(NZ11="NOR",IF(OB11>8,8,OB11),0),IF(NZ11="NOR",IF(OB11>8,8,OB11),0)))) -> 8 | OD11: =IF(NZ11="NOR",IF(OB11>10,2,IF(OB11>8,(OB11-OC11),0)),0) -> 0 | OE11: =IF(NZ11="NOR",IF(OB11<10,0,IF(OB11>10,(OB11-(OC11+OD11)),0)),0) -> 0 | OF11: =IF(NZ11="DOM",OB11,0) -> 0 | OG11: 0 | OH11: 0 | OI11: DS | OJ11: =SUM(OH11-OG11) -> 0 | OK11: =IF(OJ11>1,OJ11-1,0) -> 0 | OL11: =IF(D11="STAFF",IF(OI11="NOR",IF(OK11>8.5,8.5,OK11),0),IF(OI11="NOR",IF(OK11>8,8,OK11),IF(OJ11="CAMPO",IF(OI11="NOR",IF(OK11>8,8,OK11),0),IF(OI11="NOR",IF(OK11>8,8,OK11),0)))) -> 0 | OM11: =IF(OI11="NOR",IF(OK11>10,2,IF(OK11>8,(OK11-OL11),0)),0) -> 0 | ON11: =IF(OI11="NOR",IF(OK11<10,0,IF(OK11>10,(OK11-(OL11+OM11)),0)),0) -> 0 | OO11: =IF(OI11="DOM",OK11,0) -> 0 | OP11: 7 | OQ11: 16 | OR11: NOR | OS11: =SUM(OQ11-OP11) -> 9 | OT11: =IF(OS11>1,OS11-1,0) -> 8 | OU11: =IF(D11="STAFF",IF(OR11="NOR",IF(OT11>8.5,8.5,OT11),0),IF(OR11="NOR",IF(OT11>8,8,OT11),IF(OS11="CAMPO",IF(OR11="NOR",IF(OT11>8,8,OT11),0),IF(OR11="NOR",IF(OT11>8,8,OT11),0)))) -> 8 | OV11: =IF(OR11="NOR",IF(OT11>10,2,IF(OT11>8,(OT11-OU11),0)),0) -> 0 | OW11: =IF(OR11="NOR",IF(OT11<10,0,IF(OT11>10,(OT11-(OU11+OV11)),0)),0) -> 0 | OX11: =IF(OR11="DOM",OT11,0) -> 0 | OY11: 0 | OZ11: 0 | PA11: FE | PB11: =SUM(OZ11-OY11) -> 0 | PC11: =IF(PB11>1,PB11-1,0) -> 0 | PD11: =IF(D11="STAFF",IF(PA11="NOR",IF(PC11>8.5,8.5,PC11),0),IF(PA11="NOR",IF(PC11>8,8,PC11),IF(PB11="CAMPO",IF(PA11="NOR",IF(PC11>8,8,PC11),0),IF(PA11="NOR",IF(PC11>8,8,PC11),0)))) -> 0 | PE11: =IF(PA11="NOR",IF(PC11>10,2,IF(PC11>8,(PC11-PD11),0)),0) -> 0 | PF11: =IF(PA11="NOR",IF(PC11<10,0,IF(PC11>10,(PC11-(PD11+PE11)),0)),0) -> 0 | PG11: =IF(PA11="DOM",PC11,0) -> 0 | PH11: 7 | PI11: 16 | PJ11: NOR | PK11: =SUM(PI11-PH11) -> 9 | PL11: =IF(PK11>1,PK11-1,0) -> 8 | PM11: =IF(M11="STAFF",IF(PJ11="NOR",IF(PL11>8.5,8.5,PL11),0),IF(PJ11="NOR",IF(PL11>8,8,PL11),IF(PK11="CAMPO",IF(PJ11="NOR",IF(PL11>8,8,PL11),0),IF(PJ11="NOR",IF(PL11>8,8,PL11),0)))) -> 8 | PN11: =IF(PJ11="NOR",IF(PL11>10,2,IF(PL11>8,(PL11-PM11),0)),0) -> 0 | PO11: =IF(PJ11="NOR",IF(PL11<10,0,IF(PL11>10,(PL11-(PM11+PN11)),0)),0) -> 0 | PP11: =IF(PJ11="DOM",PL11,0) -> 0 | PR11: =COUNTIF(FG11:PP11,"NOR") -> 26 | PS11: =COUNTIF(FG11:PP11,"DS") -> 3 | PT11: =COUNTIF(FG11:PP11,"FE") -> 1 | PU11: =SUM(PR11:PT11) -> 30 | PV11: =COUNTIF(FG11:PP11,"DM") -> 0 | PY11: =COUNTIF(FG11:PP11,"SUB") -> 0 | QB11: =COUNTIF(FG11:PP11,"VA") -> 0 | QE11: =COUNTIF(FG11:PP11,"LSG") -> 0 | QH11: =COUNTIF(FG11:PP11,"LCG") -> 0 | QK11: =COUNTIF(FG11:PP11,"FA") -> 0 | QN11: =COUNTIF(J11:FF11,"FA") -> 0 | QQ11: =PU11+PV11+PY11+QB11+QE11+QH11+QK11+QN11 -> 30 | QS11: =P11+Y11++AH11+AQ11+AZ11+BI11+BR11+CA11+CJ11+CS11+DB11+DK11+DT11+EC11+EL11+EU11+FD11+FM11+FV11+GE11+GN11+GW11+HF11+HO11+HX11+IG11+IP11+IY11+JH11+JQ11+JZ11 -> 48 | QT11: =Q11+Z11++AI11+AR11+BA11+BJ11+BS11+CB11+CK11+CT11+DC11+DL11+DU11+ED11+EM11+EV11+FE11+FN11+FW11+GF11+GO11+GX11+HG11+HP11+HY11+IH11+IQ11+IZ11+JI11+JR11+KA11 -> 1 | RG11: 0
