Workbook

Sheet Matriz contrato Activos
A1: Item | B1: DNI O CE | C1: APELLIDOS Y NOMBRES | D1: CORREO | E1: CARGO | F1: AREA | G1: DIRECCION | H1: DISTRITO | I1: PROVINCIA | J1: DEPARTAMENTO | K1: TIPO DE CONTRATO | L1: BASICO | M1: ALIMENTACION | N1: HOSPEDAJE | O1: FECHA DE INGRESO A NOMINA | P1: TERMINO DE CONTRATO | Q1: 01 Prorroga | R1: 02 Prorroga | S1: 03 Prorroga | T1: 04 Prorroga | U1: 05 Prorroga | V1: 06 Prorroga | W1: 07 Prorroga | X1: 08 Prorroga | Y1: 09 Prorroga | Z1: 10 Prorroga | AA1: 11 Prorroga | AB1: 12 Prorroga | AC1: 13 Prorroga | AD1: 14 Prorroga | AE1: 15 Prorroga | AF1: 16 Prorroga | AG1: 17 Prorroga | AH1: 18 Prorroga | AI1: ULTIMA PRORROGA
A3: =A2+1 -> 1 | B3: 43290334 | C3: ABAD SALAS CARLOS ALBERTO | D3: caas30@hotmail.com | E3: AUXILIAR DE SEGURIDAD PATRIMONIAL | F3: SEGURIDAD PATRIMONIAL | G3: ESQUINA CUATRO TORRES Y KAWARINAS FRAC 2 DPTO 503 | H3: WANCHAQ | I3: CUSCO | J3: CUSCO | K3: FISCALIZABLE | L3: 1970 | M3: 0 | N3: 0 | O3: 46034 | P3: 46142 | AI3: =+MAX(O3:AH3) -> 46142
A4: =A3+1 -> 2 | B4: 48000903 | C4: ACUÑA OBREGON JULIE TERESA | D4: julie.acunaobregon@gmail.com | E4: COORDINADOR DE OFICINA TÉCNICA | F4: OFICINA TECNICA | G4: URB. UCCHULLO GRANDE P-15 | H4: CUSCO | I4: CUSCO | J4: CUSCO | K4: CONFIANZA | L4: 8000 | M4: 800 | N4: 800 | O4: 45386 | P4: 45473 | Q4: 45565 | R4: 45657 | S4: 45747 | T4: 45838 | U4: 45930 | V4: 46022 | W4: 46081 | X4: 46112 | AI4: =+MAX(O4:AH4) -> 46112
A5: =A4+1 -> 3 | B5: 43600466 | C5: AGUIRRE CAHUANA YAN PAUL | D5: tunokri@gmail.com | E5: ASISTENTE DE ALMACEN | F5: SERVICIOS GENERALES Y LOGISTICA | G5: CA. PUMACAHUA 222 URB TAHUANTINSUYO | H5: CUSCO | I5: CUSCO | J5: CUSCO | K5: FISCALIZABLE | L5: 2700 | M5: 0 | N5: 0 | O5: 45558 | P5: 45657 | Q5: 45747 | R5: 45838 | S5: 45930 | T5: 46022 | U5: 46112 | AI5: =+MAX(O5:AH5) -> 46112
A6: =A5+1 -> 4 | B6: 71405212 | C6: ALBERCA CASTILLO RUBEN AUGUSTO | D6: rb.alberca@gmail.com | E6: MODELADOR BIM | F6: BIM | G6: ASENT.H. LA PRIMAVERA MZ. F1 LT. 14 | H6: CASTILLA | I6: PIURA | J6: PIURA | K6: FISCALIZABLE | L6: 3700 | M6: 500 | N6: 500 | O6: 45909 | P6: 45991 | Q6: 46053 | R6: 46142 | AI6: =+MAX(O6:AH6) -> 46142
A7: =A6+1 -> 5 | B7: 75682513 | C7: ALFARO MARTINEZ GRECIA XIOMARA | D7: greshia.15@gmail.com | E7: ASISTENTE DE PROCURA | F7: PROCURA | G7: URB ALAMEDA LIMA NORTE II ETAPA MZ. C9 LT. 10 | H7: SANTA ROSA | I7: LIMA | J7: LIMA | K7: FISCALIZABLE | L7: 3800 | M7: 800 | N7: 800 | O7: 45787 | P7: 45869 | Q7: 45961 | R7: 46053 | S7: 46112 | AI7: =+MAX(O7:AH7) -> 46112
A8: =A7+1 -> 6 | B8: 48177998 | C8: ALVARO CASTRO JOSE LUIS | D8: jlalvarocastro@gmail.com | E8: INSTALADOR DE PVC Y VIDRIOS | F8: PRODUCCION-INTERVENCION FACONSE | G8: ASOC. PRO VIV. CAMINO REAL CUSCO MZ. T LT. 7 | H8: CUSCO | I8: CUSCO | J8: CUSCO | K8: FISCALIZABLE | L8: 3000 | M8: 0 | N8: 0 | O8: 18/10/2025 | P8: 46022 | Q8: 46053 | R8: 46081 | S8: 46112 | AI8: =+MAX(O8:AH8) -> 46112
A9: =A8+1 -> 7 | B9: 46275287 | C9: ANDRADE ROJAS MELISSA JANE | D9: melar2204@gmail.com | E9: ASISTENTE DE OFICINA TECNICA | F9: OFICINA TECNICA-INTERVENCION EISSA | G9: JR. TARAPACA 365 INT. 05 1ER. | H9: HUANUCO | I9: HUANUCO | J9: HUANUCO | K9: FISCALIZABLE | L9: 5000 | M9: 500 | N9: 500 | O9: 45727 | P9: 45808 | Q9: 45900 | R9: 45991 | S9: 46053 | T9: 46112 | AI9: =+MAX(O9:AH9) -> 46112
A10: =A9+1 -> 8 | B10: 73451822 | C10: AÑANCA QUISPE JHON WILMER | D10: jhonaaanancaquispe51@gmail.com | E10: AUXILIAR DE SEGURIDAD PATRIMONIAL | F10: SEGURIDAD PATRIMONIAL | G10: MZ R2 LT 2 ASENT.H. BAYOVAR AMPLIACION | H10: SAN JUAN DE LURIGANCHO | I10: LIMA | J10: LIMA | K10: FISCALIZABLE | L10: 1970 | M10: 0 | N10: 0 | O10: 45937 | P10: 46022 | Q10: 46053 | R10: 46081 | S10: 46112 | AI10: =+MAX(O10:AH10) -> 46112
A11: =Liquidados!A286+1 -> 11 | B11: 40548472 | C11: APAZA TITO ANTENOR | D11: antenorapazatito3@gmail.com | E11: CONDUCTOR DE VEHICULO LIVIANO | F11: SERVICIOS GENERALES Y LOGISTICA | G11: AV. LOS LIBERTADORES S/N C.POBLADO KEPASHIATO | H11: KUMPIRUSHIATO | I11: LA CONVENCION | J11: CUSCO | K11: FISCALIZABLE | L11: 2000 | M11: 375 | N11: 0 | O11: 44932 | P11: 45107 | Q11: 45199 | R11: 45291 | S11: 45473 | T11: 45382 | U11: 45565 | V11: 45657 | W11: 45688 | X11: 45716 | Y11: 45808 | Z11: 45900 | AA11: 45991 | AB11: 46053 | AC11: 46142 | AI11: =+MAX(O11:AH11) -> 46142
A12: =A11+1 -> 12 | B12: 45917823 | C12: ATAHUAMAN CHAVEZ LEYDI ODA | D12: arq.leydi.ach@gmail.com | E12: ARQUITECTO ESPECIALISTA | F12: OFICINA TECNICA | G12: URB SANTA VICTORIA B-13 | H12: HUANUCO | I12: HUANUCO | J12: HUANUCO | K12: CONFIANZA | L12: 9200 | M12: 800 | N12: 800 | O12: 45279 | P12: 45382 | Q12: 45473 | R12: 45565 | S12: 45657 | T12: 45747 | U12: 45838 | V12: 45930 | W12: 46022 | X12: 46081 | Y12: 46112 | AI12: =+MAX(O12:AH12) -> 46112
A13: =A12+1 -> 13 | B13: 03689683 | C13: ATOCHE MEDINA CARMEN LILIANA | D13: carmenatomed@gmail.com | E13: AUXILIAR DE LIMPIEZA | F13: SERVICIOS GENERALES Y LOGISTICA | G13: CALLE EL CONDOR 114 URB.SANTA ROSA | H13: SULLANA | I13: SULLANA | J13: PIURA | K13: FISCALIZABLE | L13: 1800 | M13: 375 | N13: 0 | O13: 45688 | P13: 45777 | Q13: 45869 | R13: 45961 | S13: 46053 | T13: 46142 | AI13: =+MAX(O13:AH13) -> 46142
A14: =A13+1 -> 14 | B14: 43935996 | C14: ATOCHE PECHO RANDY ARNALDO | D14: randy.atoche@gmail.com | E14: INGENIERO DE INSTALACIONES ELECTROMECANICAS | F14: COMMISSIONING | G14: JR. ALMTE. MARTIN GUISSE 1564 | H14: LINCE | I14: LIMA | J14: LIMA | K14: CONFIANZA | L14: 11000 | M14: 800 | N14: 800 | O14: 45545 | P14: 45626 | Q14: 45716 | R14: 45808 | S14: 45900 | T14: 45991 | U14: 46081 | V14: 46112 | AI14: =+MAX(O14:AH14) -> 46112
A15: =A14+1 -> 15 | B15: 46127028 | C15: AURICH ROJAS VICTOR ALBERTO | D15: krissvic_7@hotmail.com | E15: CAPATAZ ELECTRICISTA | F15: PRODUCCION-INTERVENCION EISSA | G15: MZ 42 LT 11 CENT PTAPO CENTRO | H15: PATAPO | I15: CHICLAYO | J15: LAMBAYEQUE | K15: FISCALIZABLE | L15: 5000 | M15: 500 | N15: 500 | O15: 45931 | P15: 46022 | Q15: 46053 | R15: 46112 | AI15: =+MAX(O15:AH15) -> 46112
A16: =A15+1 -> 16 | B16: 71706552 | C16: BARRETO PUMACHARA HONORIO DAVID | D16: cosmo_07_97@outlook.es | E16: OPERADOR DE RETROEXCAVADORA | F16: PRODUCCION | G16: CALLE PRINCIPAL S/N | H16: HUANCARANI | I16: PAUCARTAMBO | J16: CUSCO | K16: FISCALIZABLE | L16: 1130 | M16: 0 | N16: 0 | O16: 45894 | P16: 45991 | Q16: 46022 | R16: 46053 | S16: 46081 | T16: 46112 | AI16: =+MAX(O16:AH16) -> 46112
A17: =A16+1 -> 17 | B17: 75337871 | C17: BEDOYA ARANDA NICKOLL AILYN | D17: nickollbedoya.a@gmail.com | E17: JEFE DE ADMINISTRACION CONTRACTUAL | F17: ADMINISTRACION CONTRATUAL Y LEGAL | G17: CALLE ESPERANZA 239 DPTO. 401 | H17: MIRAFLORES | I17: LIMA | J17: LIMA | K17: CONFIANZA | L17: 14000 | M17: 1000 | N17: 1200 | O17: 44866 | P17: 45230 | Q17: 45322 | R17: 45504 | S17: 45596 | T17: 45777 | U17: 45961 | V17: 46053 | W17: 46142 | AI17: =+MAX(O17:AH17) -> 46142
A18: =A17+1 -> 18 | B18: 71414045 | C18: BERNABLE PALOMINO, ALEXANDRA DEL CARMEN | D18: carmenbernanlepalomino@gmail.com | E18: ASISTENTE DE PRODUCCIÓN | F18: PRODUCCION | G18: URB. BUENA VISTA MZ. A LT. 13 | H18: CUSCO | I18: CUSCO | J18: CUSCO | K18: NO FISCALIZABLE | L18: 4000 | M18: 375 | O18: 46028 | P18: 46112 | AI18: =+MAX(O18:AH18) -> 46112
A19: =A18+1 -> 19 | B19: 72553778 | C19: CABANILLAS VILCHEZ LUIS ALEJANDRO | D19: lcabanillasvilchez@gmail.com | E19: MODELADOR BIM | F19: BIM-INTERVENCION FACONSE | G19: URB LOS CEDROS DE LA PRADERA MZ. F LT. 04 | H19: CHICLAYO | I19: CHICLAYO | J19: LAMBAYEQUE | K19: FISCALIZABLE | L19: 3500 | M19: 500 | N19: 500 | O19: 45947 | P19: 46022 | Q19: 46081 | R19: 46112 | AI19: =+MAX(O19:AH19) -> 46112
A20: =A19+1 -> 20 | B20: 77296315 | C20: CABRERA CACERES MILLENI DARMELLY | D20: millenicabrera@gmail.com | E20: INGENIERO DE OFICINA TÉCNICA | F20: OFICINA TECNICA | G20: PJ PRIMAVERA N-152 BARRIO CONO ALUVIONICO OESTE | H20: HUARAZ | I20: HUARAZ | J20: ANCASH | K20: FISCALIZABLE | L20: 4000 | M20: 800 | N20: 800 | O20: 45386 | P20: 45473 | Q20: 45535 | R20: 45596 | S20: 45688 | T20: 45777 | U20: 45869 | V20: 45961 | W20: 46053 | X20: 46142 | AI20: =+MAX(O20:AH20) -> 46142
A21: =A20+1 -> 21 | B21: 74657049 | C21: CANALES RIOS CESAR AUGUSTO | D21: cesar.canrios@gmail.com | E21: ASISTENTE DE CALIDAD | F21: CALIDAD-INTERVENCION EISSA | G21: JR. AREQUIPA MZ. A LT. 2 | H21: EL ALTO | I21: TALARA | J21: PIURA | K21: FISCALIZABLE | L21: 4000 | M21: 500 | N21: 500 | O21: 45909 | P21: 45991 | Q21: 46053 | R21: 46142 | AI21: =+MAX(O21:AH21) -> 46142
A22: =A21+1 -> 22 | B22: 005892606 | C22: CANIZA VIERCI JOAQUIN JOSE | D22: jcaniza@consorciosrt.com | E22: Gerente Tecnico | F22: PRODUCCION | G22: CALLE LOS NARANJOS 346 | H22: SAN ISIDRO | I22: LIMA | J22: LIMA | K22: NO FISCALIZABLE | L22: 38370 | M22: 0 | N22: 0 | O22: 01/07/2025 | P22: 46203 | AI22: =+MAX(O22:AH22) -> 46203
A23: =A22+1 -> 23 | B23: 60117582 | C23: CAPARO OCHOA JOSE LUIS | D23: strong.jlco@gmail.com | E23: ASISTENTE DE CONTABILIDAD | F23: ADMINISTRACION | G23: PARQUE INDUSTRIAL MZ. E LT. 17 | H23: WANCHAQ | I23: CUSCO | J23: CUSCO | K23: FISCALIZABLE | L23: 2500 | M23: 300 | N23: 0 | O23: 45798 | P23: 45900 | Q23: 45991 | R23: 46053 | S23: 46112 | AI23: =+MAX(O23:AH23) -> 46112
A24: =A23+1 -> 24 | B24: 45656788 | C24: CARBAJAL ZUÑIGA EDWIN | D24: ednig11@gmail.com | E24: TECNICO ELECTRICISTA | F24: COMMISSIONING | G24: P.JOVEN LA ESTRELLA 2 ETAPA M-6 | H24: SANTIAGO | I24: CUSCO | J24: CUSCO | K24: FISCALIZABLE | L24: 4500 | M24: 0 | N24: 0 | O24: 45792 | P24: 45869 | Q24: 45961 | R24: 46053 | S24: 46142 | AI24: =+MAX(O24:AH24) -> 46142
A25: =A24+1 -> 25 | B25: 72217746 | C25: CASANOVA VISE FRANCO ENRIQUE | D25: franco.casanovav@gmail.com | E25: JEFE DE ADMINISTRACION DE SUBCONTRATOS | F25: PROCURA | G25: JR. SAN JACINTO 155 URB CENTRO COMERCIAL DE MONTERRICO | H25: SANTIAGO DE SURCO | I25: LIMA | J25: LIMA | K25: CONFIANZA | L25: 10500 | M25: 1000 | N25: 900 | O25: 45201 | P25: 45291 | Q25: 45473 | R25: 45565 | S25: 45657 | T25: 45382 | U25: 45747 | V25: 45838 | W25: 45930 | X25: 46022 | Y25: 46112 | AI25: =+MAX(O25:AH25) -> 46112
A26: =A25+1 -> 26 | B26: 70024630 | C26: CASTAÑEDA LOPEZ, JOHN ALDAIR | D26: ing.castanedalopez@gmail.com | E26: SUPERVISOR SSOMA | F26: SSOMA | G26: AV. TUPAC AMARU S/N C.P.M PAMPA GRANDE | H26: CHONGOYAPE | I26: CHICLAYO | J26: LAMBAYEQUE | K26: NO FISCALIZABLE | L26: 5000 | M26: 800 | N26: 800 | O26: 45996 | P26: 46081 | Q26: 46112 | AI26: =+MAX(O26:AH26) -> 46112
A27: =A26+1 -> 27 | B27: 005835751 | C27: CASTILLO AQUINO ANA LAURA | D27: anitacas321@gmail.com | E27: INGENIERO RESPONSABLE DE VALORIZACIONES | F27: COSTOS Y PRESUPUESTOS | G27: AVENIDA JAVIER PRADO OESTE 1818 | H27: SAN ISIDRO | I27: LIMA | J27: LIMA | K27: NO FISCALIZABLE | L27: 16690 | M27: 0 | N27: 0 | O27: 01/12/2024 | P27: 45991 | Q27: 46173 | AI27: =+MAX(O27:AH27) -> 46173
A28: =A27+1 -> 28 | B28: 48191321 | C28: CASTILLO LEQUERNAQUE YOJANI ANTONIA | D28: antoniacastillo93@hotmail.com | E28: ASISTENTE DE RECURSOS HUMANOS | F28: GESTION HUMANA | G28: MARISCAL CASTILLA S/N | H28: VICHAYAL | I28: PAITA | J28: PIURA | K28: FISCALIZABLE | L28: 2100 | M28: 400 | N28: 400 | O28: 45870 | P28: 45961 | Q28: 46022 | R28: 46112 | AI28: =+MAX(O28:AH28) -> 46112
A29: =A28+1 -> 29 | B29: 73111816 | C29: CASTILLO PISCOYA GUSTAVO EDUARDO | D29: gustavo080398@gmail.com | E29: ADMINISTRADOR DE SUBCONTRATOS | F29: PROCURA | G29: CALLE TACNA 231 | H29: CHICLAYO | I29: CHICLAYO | J29: LAMBAYEQUE | K29: CONFIANZA | L29: 6500 | M29: 800 | N29: 800 | O29: 45856 | P29: 45961 | Q29: 46053 | R29: 46112 | AI29: =+MAX(O29:AH29) -> 46112
A30: =A29+1 -> 30 | B30: 10105707 | C30: CASTRO LLANOS CARLOS RAUL | D30: carlos.castro@crcll.com.pe | E30: DIRECTOR DE PROYECTO | F30: PRODUCCION | G30: SEPARADORA INDUSTRIAL 3110 DPTO. 406 | H30: LA MOLINA | I30: LIMA | J30: LIMA | K30: DIRECCION | L30: 27000 | M30: 1500 | N30: 1500 | O30: 45597 | P30: 45777 | Q30: 45961 | R30: 46142 | AI30: =+MAX(O30:AH30) -> 46142
A31: =Liquidados!A287+1 -> 32 | B31: 70786569 | C31: CAYAHUALLPA QUISPE CESAR ANDRES | D31: cesar_andres1807@hotmail.com | E31: MODELADOR BIM | F31: BIM | G31: URB.SAN AGUSTIN MZ.U LT.6 | H31: SAN VICENTE DE CAÑETE | I31: CAÑETE | J31: LIMA | K31: FISCALIZABLE | L31: 4000 | M31: 500 | N31: 500 | O31: 45691 | P31: 45777 | Q31: 45869 | R31: 45961 | S31: 46053 | T31: 46142 | AI31: =+MAX(O31:AH31) -> 46142
A32: =A31+1 -> 33 | B32: 75196505 | C32: CCAPA ESPINOZA YOHELMIR | D32: yohelmirccapaespinoza@gmail.com | E32: ASISTENTE DE TI | F32: TI | G32: ASOC. PRO VIV. ALTO CUSCO MZ. F LT. 2 | H32: CUSCO | I32: CUSCO | J32: CUSCO | K32: FISCALIZABLE | L32: 2400 | M32: 0 | N32: 0 | O32: 45782 | P32: 45869 | Q32: 45961 | R32: 46053 | S32: 46142 | AI32: =+MAX(O32:AH32) -> 46142
A33: =A32+1 -> 34 | B33: 73202371 | C33: CENTURION LINARES JAIR ALEXANDER | D33: centurionjair23@gmail.com | E33: INGENIERO DE VALORIZACION Y FACTURACION | F33: PROCURA | G33: CALLE 4 MZ.C1 LT.27 URB.LOS JARDINES DE VENTANILLA 1RA.ETAPA | H33: VENTANI | I33: CALLAO | J33: PROV. CONST. DEL CALLAO | K33: CONFIANZA | L33: 6000 | M33: 800 | N33: 800 | O33: 45923 | P33: 46022 | Q33: 46112 | AI33: =+MAX(O33:AH33) -> 46112
A34: =A33+1 -> 35 | B34: 77127124 | C34: CHAPARRO CHACMANI KATHIUSCA ABIGAID | D34: abigaid.1221@gmail.com | E34: ASISTENTE DE RECURSOS HUMANOS | F34: GESTION HUMANA | G34: BELENPAMPA G-9 | H34: SANTIAGO | I34: CUSCO | J34: CUSCO | K34: CONFIANZA | L34: 3000 | M34: 375 | N34: 0 | O34: 45251 | P34: 45351 | Q34: 45443 | R34: 45535 | S34: 45626 | T34: 45716 | U34: 45808 | V34: 45900 | W34: 45991 | X34: 46053 | Y34: 46142 | AI34: =+MAX(O34:AH34) -> 46142
A35: =A34+1 -> 36 | B35: 75581956 | C35: CHILCON QUISPE LIZBETH | D35: lizbethchilcon@gmail.com | E35: MODELADOR BIM | F35: BIM | G35: JR. B. DUBLE S/N | H35: CUTERVO | I35: CUTERVO | J35: CAJAMARCA | K35: FISCALIZABLE | L35: 3500 | M35: 500 | N35: 500 | O35: 45901 | P35: 45991 | Q35: 46053 | R35: 46142 | AI35: =+MAX(O35:AH35) -> 46142
A36: =A35+1 -> 37 | B36: 23981390 | C36: CONDORHUACHO CORNEJO MARGOT | D36: margot.4540@gmail.com | E36: AUXILIAR DE LIMPIEZA | F36: SERVICIOS GENERALES Y LOGISTICA | G36: ASOC. PRO.VIV. CAMINO REAL MZ. E LT. 1 | H36: CUSCO | I36: CUSCO | J36: CUSCO | K36: FISCALIZABLE | L36: 1800 | M36: 375 | N36: 0 | O36: 44575 | P36: 44666 | Q36: 44681 | R36: 44696 | S36: 44834 | T36: 45351 | U36: 44865 | V36: 45322 | W36: 45138 | X36: 45230 | Y36: 45260 | Z36: 45443 | AA36: 45535 | AB36: 45626 | AC36: 45716 | AD36: 45808 | AE36: 45991 | AF36: 46022 | AG36: 46112 | AI36: =+MAX(O36:AH36) -> 46112
A37: =A36+1 -> 38 | B37: 40308469 | C37: CORAHUA CHALCO KATY | D37: katty_c_ch@hotmail.com | E37: ASISTENTE DE TESORERIA | F37: FINANZAS | G37: ASOC. LOS INCAS MZ. F LT. 5 | H37: CUSCO | I37: CUSCO | J37: CUSCO | K37: FISCALIZABLE | L37: 4000 | M37: 375 | N37: 0 | O37: 44962 | P37: 45138 | Q37: 45230 | R37: 45260 | S37: 45443 | T37: 45351 | U37: 45535 | V37: 45626 | W37: 45716 | X37: 45808 | Y37: 45900 | Z37: 45991 | AA37: 46081 | AB37: 46112 | AI37: =+MAX(O37:AH37) -> 46112
A38: =Liquidados!A288+1 -> 40 | B38: 47110375 | C38: CRUZADO LOLOY ANCELMO | D38: acloloy2020@gmail.com | E38: CAPATAZ ALBAÑIL | F38: PRODUCCION | G38: CALLE VICTOR ANDRES BELAUNDE 115 CENTRO MONSEFU | H38: MONSEFU | I38: CHICLAYO | J38: LAMBAYEQUE | K38: FISCALIZABLE | L38: 5000 | M38: 500 | N38: 500 | O38: 45616 | P38: 45716 | Q38: 45808 | R38: 45900 | S38: 45961 | T38: 46022 | U38: 46112 | AI38: =+MAX(O38:AH38) -> 46112
A39: =A38+1 -> 41 | B39: 43801267 | C39: CRUZADO LOLOY HUGO FELIX | D39: hugocruzadololoy@gmail.com | E39: CAPATAZ ALBAÑIL | F39: PRODUCCION | G39: ASOC. PROVIV. VIRGEN DE LA PUERTA MZ. B LT. 15 | H39: CARABAYLLO | I39: LIMA | J39: LIMA | K39: FISCALIZABLE | L39: 5000 | M39: 500 | N39: 500 | O39: 45610 | P39: 45688 | Q39: 45777 | R39: 45869 | S39: 45961 | T39: 46053 | U39: 46112 | AI39: =+MAX(O39:AH39) -> 46112
A40: =A39+1 -> 42 | B40: 70887797 | C40: CUELLAR OVALLE BURGOS ANTERO | D40: 144952@unsaac.edu.pe | E40: ASISTENTE DE PRODUCCIÓN | F40: PRODUCCION | G40: URB. LOS JARDINES B-15 | H40: WANCHAQ | I40: CUSCO | J40: CUSCO | K40: FISCALIZABLE | L40: 4000 | M40: 0 | N40: 0 | O40: 45627 | P40: 45716 | Q40: 45808 | R40: 45900 | S40: 45961 | T40: 46022 | U40: 46112 | AI40: =+MAX(O40:AH40) -> 46112
A41: =A40+1 -> 43 | B41: 007453650 | C41: CUELLAR TERAN VANESSA | D41: vanessa.cuellar@hotmail.com | E41: Responsable de Subcontratos | F41: PRODUCCION | G41: CALLE MANUEL UGARTE Y MOSC 991 | H41: SAN ISIDRO | I41: LIMA | J41: LIMA | K41: NO FISCALIZABLE | L41: 21870.9 | M41: 0 | N41: 0 | O41: 01/12/2024 | P41: 45991 | Q41: 46081 | AI41: =+MAX(O41:AH41) -> 46081
...

Sheet Liquidados
A2: Item | B2: DNI O CE | C2: APELLIDOS Y NOMBRES | E2: CARGO | G2: DIRECCIÓN | H2: Distrito | I2: PROVINCIA | J2: DEPARTAMENTO | L2: FECHA INGRESO NOMINA | M2: TERMINO DE CONTRATO | N2: 1° PRORROGA | O2: 2° PRORROGA | P2: 3° PRORROGA | Q2: 4° PRORROGA | R2: 5° PRORROGA | S2: 6° PRORROGA | T2: 7° PRORROGA | U2: 8° PRORROGA | V2: 9° PRORROGA | W2: 10° PRORROGA | X2: 11° PRORROGA | Y2: 12° PRORROGA | Z2: 13° PRORROGA | AA2: 14° PRORROGA | AB2: 15° PRORROGA | AC2: 16° PRORROGA | AD2: 17° PRORROGA | AE2: 18° PRORROGA | AF2: 19° PRORROGA | AG2: 20° PRORROGA | AH2: 21° PRORROGA | AI2: ULTIMA PRORROGA | AJ2: OBS
A3: 3 | B3: 71432911 | C3: ANGELES PUMA JESSICA MELISSA | E3: ASISTENTE DE RECURSOS HUMANOS | G3: 44918 | H3: 44948 | L3: 44918 | M3: 44948
A4: 9 | B4: 46112567 | C4: BALLENA CASTILLO PEDRO ENRIQUE | E4: INGENIERO DE INSTALACIONES | L4: 44927 | M4: 45107 | N4: 45199 | AK4: FALTA FIRMA AITCIN Y HAVAI
A5: 12 | B5: 42407819 | C5: BOLOÑOS SARAVIA LUDWEG | E5: MEDICO OCUPACIONAL | G5: 44994 | H5: 45015 | L5: 44994 | M5: 45015
A6: 35 | B6: 10001181 | C6: FLORES DURAN JAIME ENRIQUE | E6: GERENTE GENERAL | G6: 44958 | H6: 45322 | L6: 44958 | M6: 45322
A7: 52 | B7: 46003549 | C7: JUAREZ DIOSES JUAN JESUS | E7: JEFE DE RECURSOS HUMANOS | G7: 44914 | H7: 45064 | L7: 44914 | M7: 45064
A8: 61 | B8: 40738865 | C8: LOPEZ ZARATE ROGER JAVIER | E8: JEFE DE SSOMA | G8: 44767 | H8: 44834 | L8: 44767 | M8: 44834
A9: 62 | B9: 40738865 | C9: LOPEZ ZARATE ROGER JAVIER | E9: JEFE DE SSOMA | G9: 44564 | H9: 44666 | L9: 44564 | M9: 44666
A10: 69 | B10: 42064066 | C10: MATA REINOZO WILLIAM FERNANDO | E10: JEFE DE COSTOS Y PRESUPUESTOS | L10: 44545 | M10: 44681 | N10: 44712 | O10: liquidado | P10: 44834 | Q10: 44865 | R10: 44957 | S10: 30/06/2023 | AK10: BARRIOS, HAVAI Y GANDINI (FALTA) | AL10: 44835 | AM10: 44865 | AN10: BARRIOS, HAVAI Y GANDINI
A11: 70 | B11: 06719981 | C11: MAXIMO SANDOVAL FRANCISCO AGUSTIN | G11: 44564 | H11: 44681 | L11: 44564 | M11: 44681
B12: 44628256 | C12: RODRIGUEZ MONROY CESAR RAUL | E12: ADMINISTRADOR DE CONTRATOS | L12: OK | M12: OK | N12: 01/03/2022 AL 31/10/2022
A13: 87 | B13: 43799720 | C13: RODRIGUEZ ZAPATA LUIS FELIPE | E13: GERENTE DE CALIDAD | G13: 44565 | H13: 44666 | L13: 44565 | M13: 44666
A14: 89 | B14: 23996122 | C14: ROJAS ZAPANA WILLIAM WASHINGTON | E14: AUXILIAR DE MANTENIMIENTO | G14: 44571 | H14: 44666 | I14: 45199 | L14: 44571 | M14: 44666
A15: 92 | B15: 73330160 | C15: ROSALES SALINAS RENATO | E15: ASISTENTE DE RECURSOS HUMANOS | G15: 44927 | H15: 44948 | L15: 44927 | M15: 44948
A16: 93 | B16: 40801957 | C16: SAAVEDRA SANCARRANCO CONCEPCION ANABELI | E16: JEFE DE PROCURA | L16: OK | M16: OK
A17: 102 | B17: 70103838 | C17: VALLE SALAS KATIANA DANAIT | E17: ADMINISTRADOR DE OBRA | L17: OK | M17: OK | N17: 25/01/2022 AL 30/09/2022 | O17: 44865 | AK17: HERNIQUE GANDINI | AM17: 44865 | AN17: HERNIQUE GANDINI
A18: 104 | B18: 23990472 | C18: VENERO DORADO JOHN PAVEL | G18: 44580 | H18: 44666 | L18: 44580 | M18: 44666
A19: 111 | B19: 71656130 | C19: ZAMBRANO VARGAS GERARDO JOSE | E19: MODELADOR BIM | G19: 45040 | H19: 45138 | L19: 45040 | M19: 45138
A20: 50 | B20: 40403833 | C20: LEON JIMENEZ MARCO ANTONIO | E20: JEFE DE ADMINISTRACION | G20: 44550 | H20: 45031 | I20: 45291 | L20: 44550 | M20: 44666
A21: 53 | B21: 43247579 | C21: LLERENA HUARMIYURI CARLOS MAGNO | E21: CONTROL DOCUMENTARIO | L21: 44964 | M21: 45138 | N21: 45230
A22: 3 | B22: 63436592 | C22: APASA CRUZ ABEL | E22: AUXILIAR DE MANTENIMIENTO | L22: 44935 | M22: 45107 | N22: 45199 | AK22: FALTA FIRMA AITCIN Y HAVAI
A23: 11 | B23: 24000956 | C23: CARBAJAL LAURA ROBERTO CARLOS | E23: GERENTE DE OFICINA TECNICA | L23: 44998 | M23: 45382
A24: 25 | B24: 48184564 | C24: CRUZ GARAVITO ANTONY | E24: FINANCIERO | L24: 44958 | M24: 45138 | N24: 45230
A25: 35 | B25: 46108362 | C25: GONZALES CERVANTES MARIA ADRIANA | E25: ARQUITECTA ESPECIALISTA | L25: 44986 | M25: 45169
A26: 69 | B26: 45283241 | C26: PAREDES TRUJILLO VILLY RICHARD | E26: INGENIERO DE PROCURA | L26: 44998 | M26: 45169
A27: 78 | B27: 23996122 | C27: ROJAS ZAPANA WILLIAM WASHINGTON | E27: AUXILIAR DE MANTENIMIENTO | L27: 44935 | M27: 45107 | N27: 45199 | AK27: FALTA FIRMA AITCIN Y HAVAI
B28: 48515190 | C28: MENDEZ TORRES ALEXIS HUMBERTO | E28: ANALISTA DE COSTOS | L28: 45114 | M28: 45199
B29: 43467715 | C29: SILVA MAMANI DAVID | E29: CONDUCTOR DE VEHICULO LIVIANO | L29: 45193 | M29: 45199
B30: 10723251 | C30: FLORES VARGAS EDWIN CARLOS | E30: PARAMEDICO CONDUCTOR DE AMBULANCIA | L30: 45089 | M30: 45169
A31: 62 | B31: 16731445 | C31: AMENERO RIVERA RICARDO | E31: GERENTE DE DISEÑO | G31: ARQUITECTURA | L31: 44593 | M31: 44681 | P31: 01/05/2022 al 30/06/2022 | Q31: 44834 | R31: 44865 | T31: 44926 | U31: 44957 | V31: 45107 | W31: 45291 | AK31: OK | AM31: 44743 | AN31: 44834 | AO31: BARRIOS, HAVAI Y GANDINI (FALTA) | AP31: 44835 | AQ31: 44865 | AR31: BARRIOS, HAVAI Y GANDINI | AS31: 44866 | AT31: 44926 | AU31: BARRIOS, HAVAI Y GANDINI | AV31: 44958 | AW31: 45107 | AX31: BARRIOS Y HAVAI | AY31: 45108 | AZ31: 45291 | BA31: AITCIN Y HAVAI
A32: 112 | B32: 07885306 | C32: ARATA DELGADO, MARIA PIA | E32: JEFE DE DISEÑO | G32: DISEÑO | L32: 45159 | M32: 45291
A33: 5 | B33: 45119589 | C33: ARISTA MAS CARLOS MARX | E33: JEFE DE PLANEAMIENTO | G33: PLANEAMIENTO | L33: 44861 | M33: 45042 | P33: 45291 | AK33: HAVAI Y AITCIN | AM33: 45043 | AN33: 45137 | AO33: FALTA FIRMA AITCIN Y HAVAI | BC33: L
A34: 6 | B34: 41335487 | C34: BACA SOTOMAYOR YENI | E34: ENFERMERA OCUPACIONAL | L34: 45096 | M34: 45199 | P34: 45291 | AK34: HAVAI Y AITCIN | BC34: L
A35: 9 | B35: 23945249 | C35: CABALLERO COELLO ALCIRA SIRLEY | E35: ENFERMERA | L35: 44581 | M35: 44666 | P35: 16/04/2022 al 30/06/2022 | Q35: 44834 | R35: 44865 | T35: 44957 | U35: 45138 | V35: 45230 | AK35: ROJAS CLAUDIO | AM35: 44743 | AN35: 44834 | AO35: BARRIOS, HAVAI Y GANDINI (FALTA) | AP35: 44866 | AQ35: 44957 | AR35: BARRIOS Y GANDINI | AS35: 44958 | AT35: 45138 | AU35: BARRIOS Y HAVAI | BC35: X
A36: 97 | B36: 42249108 | C36: CARRION PEREZ, ALAN JOSHEP | E36: SUPERVISOR SSOMA | L36: 45139 | M36: 45230 | BC36: X
A37: 14 | B37: 46168855 | C37: CCAULLA GOMEZ CARLOS EDUARDO | E37: ASISTENTE DE VALORIZACIONES | L37: 44566 | M37: 44666 | P37: 16/04/2022 al 30/06/2022 | Q37: 44834 | R37: 44865 | T37: 44957 | U37: 44985 | V37: 45138 | W37: 45230 | AK37: OK | AM37: 44743 | AN37: 44834 | AO37: BARRIOS, HAVAI Y GANDINI (FALTA) | AP37: 44866 | AQ37: 44957 | AR37: BARRIOS, HAVAI Y GANDINI | AS37: 44958 | AT37: 44985 | AU37: BARRIOS Y HAVAI | AV37: 44986 | AW37: 45138 | AX37: BARRIOS Y HAVAI | BC37: X
A38: 27 | B38: 40023502 | C38: ESPINOZA RIVERA ELIZABETH | E38: INGENIERO DE CALIDAD | L38: 44967 | M38: 45138 | P38: 45322 | AK38: BARRIOS Y HAVAI
A39: 119 | B39: 10723251 | C39: FLORES VARGAS EDWIN CARLOS | L39: 45089 | M39: 45169
A40: 30 | B40: 73512089 | C40: GARAY CHAMORRO DERLY KIARA | E40: ARQUITECTA DE OFICINA TECNICA | G40: OFICINA TECNICA | L40: 44958 | M40: 45137 | P40: 45230 | Q40: 45260 | R40: 45291 | AK40: BARRIOS Y HAVAI | BC40: L
A41: 61 | B41: 23967045 | C41: PACHECO LETONA JULIO CESAR | E41: RESPONSABLE DE SITIO | G41: PRODUCCION | L41: 44760 | M41: 44834 | P41: 44865 | Q41: 44957 | R41: 45138 | T41: 45230 | U41: 45322 | AK41: GANDINI | AM41: 44866 | AN41: 44957 | AO41: BARRIOS Y GANDINI | AP41: 44958 | AQ41: 45138 | AR41: BARRIOS Y HAVAI | BC41: L
...
